Workbook

Sheet Balance Sheet
B1: HOUSING DEVELOPMENT AND INFRASTRUCTURE LIMITED
B2: Balance Sheet as at 31st March 2025 | (INR in Lakhs)
B3: Note | C3: Particulars | D3: 31st March 2025 (Audited) | E3: 31st March 2024 (Audited)
B4: ASSETS
B5: Non-Current Assets
B6: 2 | C6: Property, Plant and Equipment (Net) | D6: 9604.54 | E6: 9838.42
B7: 3 | C7: Investment Property | D7: 10350.67 | E7: 10350.67
B8: 4 | C8: Non-Current Investments | D8: 48888.74 | E8: 48936.24
B9: 5 | C9: Other Non-Current Financial Assets | D9: 818.31 | E9: 818.31
B10: Current Assets
B11: 6 | C11: Inventories | D11: 281468.68 | E11: 283744.04
B12: 7 | C12: Current Investments | D12: 101.58 | E12: 101.58
B13: 8 | C13: Trade Receivables | D13: 40633.99 | E13: 39871.23
B14: 9 | C14: Cash and Cash Equivalents | D14: 386.57 | E14: 364.71
B15: 10 | C15: Bank Balances Other than above | D15: 1264 | E15: 1337.04
B16: 11 | C16: Other Current Financial Assets | D16: 1090.9 | E16: 1090.9
B17: 12 | C17: Other Current Assets | D17: 125.34 | E17: 124.84
B18: 13 | C18: Current Tax Assets (Net) | D18: 23.06 | E18: 10.63
B19: TOTAL ASSETS | D19: 394756.39 | E19: 396588.61
B21: EQUITY AND LIABILITIES
B22: Equity
B23: 14 | C23: Equity Share Capital | D23: 47400.4 | E23: 47400.4
B24: 15 | C24: Other Equity (Deficit) | D24: -276893.89 | E24: -276892.76
B25: Non-Current Liabilities
B26: 16 | C26: Non-Current Borrowings
B27: 18 | C27: Non-Current Provisions
B28: Current Liabilities
B29: 16 | C29: Current Borrowings | D29: 248363.72 | E29: 248363.72
B30: 17 | C30: Trade Payables | D30: 41840.14 | E30: 41749.35
B31: 18 | C31: Other Financial Liabilities (Current) | D31: 125858.81 | E31: 126129.82
B32: 19 | C32: Other Current Liabilities | D32: 207242.71 | E32: 208893.57
B33: 20 | C33: Current Provisions | D33: 944.5 | E33: 944.5
B34: TOTAL EQUITY AND LIABILITIES | D34: 394756.39 | E34: 396588.61
C36: source : Finanacial statement from company website
B37: Note: Auditors (Dayal & Lohia) issued a Disclaimer of Opinion. Net worth is deeply negative. Company is under CIRP since August 2019.

Sheet Profit & Loss
B1: Statement of Profit and Loss for the Year Ended 31st March 2025 | (INR in Lakhs)
B2: Statement of Profit and Loss for the Year Ended 31st March 2025 | (INR in Lakhs)
B3: Note | C3: Particulars | D3: Year Ended 31st March 2025 | E3: Year Ended 31st March 2024
B4: INCOME
B5: 22 | C5: Revenue from Operations | D5: 3395.61 | E5: 204.59
B6: 23 | C6: Other Income | D6: 196.38 | E6: 115.72
B7: Total Income | D7: 3591.99 | E7: 320.31
B9: EXPENSES
B10: 24 | C10: Changes in Inventories of Finished Goods & WIP | D10: 2275.36
B11: 25 | C11: Employee Benefits Expense | D11: 146.5 | E11: 223.94
B12: 2&3 | C12: Depreciation and Amortisation Expense | D12: 253.04 | E12: 262.43
B13: 26 | C13: Other Expenses | D13: 937.39 | E13: 876.82
B14: Total Expenses | D14: 3612.29 | E14: 1363.2
C16: Loss Before Exceptional Items and Tax | D16: -20.3 | E16: -1042.89
B17: 27 | C17: Exceptional Items – Reversal of Depreciation on Fixed Assets | D17: 19.17 | E17: 11.24
B18: Loss Before Tax | D18: -1.13 | E18: -1031.65
C19: Tax Expense – Current Tax
C20: Tax Expense – Deferred Tax
B21: Loss for the Period (PAT) | D21: -1.13 | E21: -1031.65
B23: 28 | C23: Basic Earnings Per Share (₹) | D23: 0 | E23: -0.22
B24: 28 | C24: Diluted Earnings Per Share (₹) | D24: 0 | E24: -0.22
C26: source : Finanacial statement from company website

Sheet Cash Flow
B1: HOUSING DEVELOPMENT AND INFRASTRUCTURE LIMITED
B2: Cash Flow Statement for the Year Ended 31st March 2025 | (INR in Lakhs)
C3: Particulars | D3: 31st March 2025 | E3: 31st March 2024
C4: Cash Flow from Operating Activities
C5: Loss for the Period | D5: -1.13 | E5: -1031.65
C6: Adjustments:
C7: Depreciation & Amortisation | D7: 253.04 | E7: 262.43
C8: Interest Received | D8: -10.67 | E8: 19.21
C9: Non-Cash Adjustments during the year | D9: 19.17
C10: Investment Written Off during the year | D10: -47.5
C11: Operating Profit before Working Capital Changes | D11: 290.91 | E11: -799.68
C12: Decrease/(Increase) in Inventories | D12: 2275.36
C13: Decrease/(Increase) in Trade Receivables | D13: -743.6 | E13: 547.75
C14: (Decrease)/Increase in Trade Payables | D14: 90.79 | E14: 263.08
C15: (Decrease)/Increase in Financial Liabilities | D15: -271.01 | E15: 1067.64
C16: (Decrease)/Increase in Other Current Assets | D16: -0.51 | E16: 1.06
C17: (Decrease)/Increase in Other Current Liabilities | D17: -1650.85 | E17: -36.83
C18: Net Movement in Working Capital | D18: -299.83 | E18: 1842.69
C19: Cash Generated from Operations | D19: -9.92
C20: Direct Taxes Paid (Net) | D20: -12.43 | E20: 1043.02
C21: Net Cash from Operating Activities (before exceptional) | D21: -21.35 | E21: -10.63
C22: Exceptional Items | D22: -19.17 | E22: -11.24
B23: A NET | C23: Net Cash from Operating Activities (after exceptional) | D23: -40.52 | E23: 1021.15
C24: Cash Flows from Investing Activities
B25: B NET | C25: Net Cash Used in Investing Activities
C26: Cash Flows from Financing Activities
B27: C NET | C27: Net Cash from Financing Activities
C28: Net Increase/(Decrease) in Cash & Equivalents | D28: -40.52 | E28: 1021.15
C29: Cash at Beginning of Year | D29: 1621.82 | E29: 600.67
C30: Cash at End of Year | D30: 1581.31 | E30: 1621.82
B33: NOTES TO CASH FLOW STATEMENT
C34: Note 1: Components of Cash and Cash Equivalents (as at year end)
C35: Particulars | D35: 31st March 2025 | E35: 31st March 2024
C36: Cash on Hand | D36: 67.79 | E36: 67.69
C37: Balances with Banks:
C38: - On Current Account | D38: 268.8 | E38: 247.04
C39: - On Escrow Account | D39: 49.98 | E39: 49.98
C40: - On Deposit Account (Fixed Deposits < 1 year maturity) | D40: 1194.94 | E40: 1257.31
C41: - In Overdraft with Bank | D41: -0.2 | E41: -0.2
C42: Total Cash and Cash Equivalents (A) | D42: 1581.31 | E42: 1621.82
...

Sheet Notes to Accounts
B1: HOUSING DEVELOPMENT AND INFRASTRUCTURE LIMITED Notes Forming Part of the Financial Statements (INR in Lakhs)
B2: Particulars | C2: Note No. | D2: 31st March 2025 | E2: 31st March 2024
B4: Note 2: Property, Plant and Equipment (PPE) and Intangible Assets (Net Block)
B5: Description | C5: Note No. | D5: As at 31st March 2025 | E5: As at 31st March 2024
B6: Freehold Land and Buildings | D6: 9526.51 | E6: 9735.55
B7: Plant and Machinery | D7: 69.35 | E7: 98.39
B8: Furniture and Fixtures | D8: 0.5 | E8: 0
B9: Vehicles | D9: 6.19 | E9: 4.5
B10: Office Equipments | D10: 0.11 | E10: -0.1
B11: Computers | D11: 0.31 | E11: -0.91
B12: Property, Plant and Equipment (A) | D12: 9602.97 | E12: 9838.43
B13: Intangible Assets (B) | D13: 1.57
B14: Grand Total (A+B) | D14: 9604.54 | E14: 9838.43
B15: Investment Property
B16: Lease Out Property | D16: 10350.67 | E16: 10350.67
B17: Total Investment Property | D17: 10350.67 | E17: 10350.67
B18: Auditor Note: (i) RP unable to physically verify all PPE. (ii) Documents for immovable property investments of Rs.23,764.28 lakhs not available. (iii) No impairment assessment made due to absence of sufficient information. (iv) No revaluation during the year.
B20: Note 4: Non-Current Investments
B21: Particulars | C21: Note No. | D21: 31st March 2025 | E21: 31st March 2024
B22: Investments in Equity Instruments - Other than Trade (Unquoted Shares)
B23: Punjab & Maharashtra Co-op Bank Ltd (1,90,000 shares @ ₹25/-) | E23: 47.5
B24: Dreams The Mall Company Ltd (93,957 shares @ ₹10/-) | D24: 9.4 | E24: 9.4
B25: In Subsidiary Company (Unquoted Shares)
B26: Privilege Power & Infrastructure Pvt Ltd (1,61,05,000 shares @ ₹100/-) | D26: 36145.79 | E26: 36145.79
B27: Mazda Estates Pvt Ltd (4,10,000 shares @ ₹10/-) | D27: 2746.35 | E27: 2746.35
B28: Guruashish Construction Pvt Ltd (31,00,000 shares @ ₹100/-) | D28: 29948.75 | E28: 29948.75
B29: Less: Provision for Investment in Subsidiaries | D29: -29948.75 | E29: -29948.75
B30: BKC Developers Pvt Ltd
B31: Lashkaria Construction Pvt Ltd (98,500 shares @ ₹10/-) | D31: 9297.2 | E31: 9297.2
B32: BKC Inspire (69,00,000 shares @ ₹10/-) | D32: 690 | E32: 690
B33: Total Non-Current Investments | D33: 48888.74 | E33: 48936.24
B34: Aggregate amount of unquoted investments | D34: 48888.74 | E34: 48936.24
B35: Aggregate amount of impairment in value of investments | D35: -29948.75 | E35: -29948.75
B36: Auditor Note: Details & documents not available. No impairment assessment made due to insufficient info. Guruashish Construction Pvt Ltd ordered for liquidation by NCLT (04 Sep 2020); provision of INR 29,948.75 lakhs made. Audited financial statements of subsidiaries for FY 2020-21 to 2024-25 not received.
B38: Note 5: Other Non-Current Financial Assets
B39: Particulars | C39: Note No. | D39: 31st March 2025 | E39: 31st March 2024
B40: Security Deposit | D40: 41.23 | E40: 41.23
B41: Guarantee Obligation Commission | D41: 777.08 | E41: 777.08
B42: Total | D42: 818.31 | E42: 818.31
B43: Auditor Note: Details & documents regarding Guarantee Obligation Commission of INR 777.08 lakhs not available.
...

Sheet Beta
D1: Nifty50 | H1: HDIL
D2: Date | E2: Close | F2: Daily return | H2: Date | I2: Close Price | J2: Daily Returns
D3: 45658 | E3: 23742.9 | H3: 45658 | I3: 3.89
D4: 45659 | E4: 24188.65 | F4: =E4/E3-1 -> 0.018774034 | H4: 45659 | I4: 3.89 | J4: =I4/I3-1 -> 0
D5: 45660 | E5: 24004.75 | F5: =E5/E4-1 -> -0.0076027393 | H5: 45660 | I5: 3.84 | J5: =I5/I4-1 -> -0.01285347
D6: 45663 | E6: 23616.05 | F6: =E6/E5-1 -> -0.016192629 | H6: 45663 | I6: 3.8 | J6: =I6/I5-1 -> -0.010416667
D7: 45664 | E7: 23707.9 | F7: =E7/E6-1 -> 0.0038893041 | H7: 45664 | I7: 3.79 | J7: =I7/I6-1 -> -0.0026315789
D8: 45665 | E8: 23688.95 | F8: =E8/E7-1 -> -0.00079931162 | H8: 45665 | I8: 3.71 | J8: =I8/I7-1 -> -0.021108179 | N8: beta | O8: =SLOPE(F4:F176,J4:J176) -> 0.038349302
D9: 45666 | E9: 23526.5 | F9: =E9/E8-1 -> -0.0068576277 | H9: 45666 | I9: 3.71 | J9: =I9/I8-1 -> 0 | O9: =_xlfn.COVARIANCE.S(F4:F176,J$4:J$176)/_xlfn.VAR.S(J$4:J$176) -> 0.038349302
D10: 45667 | E10: 23431.5 | F10: =E10/E9-1 -> -0.0040379997 | H10: 45667 | I10: 3.54 | J10: =I10/I9-1 -> -0.045822102
D11: 45670 | E11: 23085.95 | F11: =E11/E10-1 -> -0.014747242 | H11: 45670 | I11: 3.44 | J11: =I11/I10-1 -> -0.028248588
D12: 45671 | E12: 23176.05 | F12: =E12/E11-1 -> 0.0039028067 | H12: 45671 | I12: 3.49 | J12: =I12/I11-1 -> 0.014534884
D13: 45672 | E13: 23213.2 | F13: =E13/E12-1 -> 0.0016029479 | H13: 45672 | I13: 3.51 | J13: =I13/I12-1 -> 0.005730659
D14: 45673 | E14: 23311.8 | F14: =E14/E13-1 -> 0.0042475833 | H14: 45673 | I14: 3.56 | J14: =I14/I13-1 -> 0.014245014
D15: 45674 | E15: 23203.2 | F15: =E15/E14-1 -> -0.0046585849 | H15: 45674 | I15: 3.53 | J15: =I15/I14-1 -> -0.0084269663
D16: 45677 | E16: 23344.75 | F16: =E16/E15-1 -> 0.0061004517 | H16: 45677 | I16: 3.7 | J16: =I16/I15-1 -> 0.04815864
D17: 45678 | E17: 23024.65 | F17: =E17/E16-1 -> -0.013711862 | H17: 45678 | I17: 3.87 | J17: =I17/I16-1 -> 0.045945946
D18: 45679 | E18: 23155.35 | F18: =E18/E17-1 -> 0.0056765249 | H18: 45679 | I18: 4.03 | J18: =I18/I17-1 -> 0.041343669
D19: 45680 | E19: 23205.35 | F19: =E19/E18-1 -> 0.0021593282 | H19: 45680 | I19: 4.23 | J19: =I19/I18-1 -> 0.049627792
D20: 45681 | E20: 23092.2 | F20: =E20/E19-1 -> -0.0048760307 | H20: 45681 | I20: 4.44 | J20: =I20/I19-1 -> 0.04964539
D21: 45684 | E21: 22829.15 | F21: =E21/E20-1 -> -0.011391292 | H21: 45684 | I21: 4.21 | J21: =I21/I20-1 -> -0.051801802
... D176: 46022 | E176: 26129.6 | F176: =E176/E175-1 -> 0.0073538341 | H176: 46022 | I176: 2.4 | J176: =I176/I175-1 -> 0

Sheet WACC
B1: HOUSING DEVELOPMENT & INFRASTRUCTURE LTD
B4: (All amounts in ₹ Lakhs)
B5: Wegithr Average Cost Of Capital
B7: All Figure are in INR unless Stated Otherwise
K9: Weighted Average Cost of Capital
G10: Equity / | H10: Debt/ | I10: Cost of | J10: Cost of
B11: Name oF Company | C11: Country | D11: Total Equity | E11: Total Debt | F11: Tax Rate 1 | G11: Weights | H11: Weights | I11: Equity | J11: Debt | K11: Cost of Equity | N11: =I12 -> 0.066042628
B12: HOUSING DEVELOPMENT & INFRASTRUCTURE LTD | C12: Iindia | D12: =IFERROR(SUM('Balance Sheet'!D23),0) -> 47400.4 | E12: =IFERROR(SUM('Balance Sheet'!D26),0) -> 0 | F12: 0.3 | G12: =IFERROR(D12/SUM(D12:E12),0) -> 1 | H12: =IFERROR(E12/(SUM(D12:E12)),0) -> 0 | I12: =Q34 -> 0.066042628 | J12: =F42 -> 0 | K12: Equity Weight | N12: =G12 -> 1
K13: Cost of Debt | N13: =J12 -> 0
B14: Total Capital | D14: =SUM(D12:E12) -> 47400.4 | K14: Debt Weight | N14: =H12 -> 0
K15: WACC | N15: =(N11*N12)+(N13*N14) -> 0.066042628
B16: Capital Assets Pricing Model
C18: Nifty 50
L19: HDIL
B20: Date | C20: Close Price | D20: Yearly Return | L20: Date | M20: Close Price | N20: Yearly Return
B21: 42508 | C21: 7870.15 | F21: Average Return | H21: =AVERAGE(D22:D30) -> 0.15973165 | I21: =MEDIAN(D22:D30) -> 0.11637623 | L21: 42508 | M21: 91.45 | P21: Average Return | R21: =AVERAGE(N22:N30) -> 0.042694611
B22: 42873 | C22: 9429.45 | D22: =C22/C21-1 -> 0.19812837 | F22: CAGR | G22: =_xlfn.RRI(10,C21,C30) -> 0.12227899 | L22: 42873 | M22: 90.7 | N22: =M22/M21-1 -> -0.0082012028
B23: 43238 | C23: 10596.4 | D23: =C23/C22-1 -> 0.12375589 | F23: Total Market Return | H23: =H21 -> 0.15973165 | L23: 43238 | M23: 28.3 | N23: =M23/M22-1 -> -0.68798236 | P23: Total Market Return | R23: =R21 -> 0.042694611
B24: 43605 | C24: 11828.25 | D24: =C24/C23-1 -> 0.11625175 | L24: 43605 | M24: 21.9 | N24: =M24/M23-1 -> -0.22614841 | P24: Beta2 | Q24: =Beta!O8 -> 0.038349302
B25: 43969 | C25: 8823.25 | D25: =C25/C24-1 -> -0.2540528 | L25: 43969 | M25: 1.6 | N25: =M25/M24-1 -> -0.92694064 | P25: =_xlfn.COVARIANCE.S(N22:N30,D22:D30)/_xlfn.VAR.S(D22:D30) -> 3.1987486 | Q25: Beta1 | R25: using cov
B26: 44334 | C26: 15108.1 | D26: =C26/C25-1 -> 0.71230556 | L26: 44334 | M26: 4.75 | N26: =M26/M25-1 -> 1.96875 | P26: =SLOPE(N22:N30,D22:D30) -> 3.1987486 | R26: slope
B27: 44699 | C27: 16240 | D27: =C27/C26-1 -> 0.074920076 | L27: 44699 | M27: 6.05 | N27: =M27/M26-1 -> 0.27368421
B28: 45064 | C28: 18129.95 | D28: =C28/C27-1 -> 0.11637623 | L28: 45068 | M28: 2.45 | N28: =M28/M27-1 -> -0.59504132
B29: 45433 | C29: 22529.05 | D29: =C29/C28-1 -> 0.2426427 | L29: 45433 | M29: 4.65 | N29: =M29/M28-1 -> 0.89795918
B30: 45796 | C30: 24945.45 | D30: =C30/C29-1 -> 0.10725707 | L30: 45796 | M30: 3.2 | N30: =M30/M29-1 -> -0.31182796 | P30: 0.0638 | Q30: RF | R30: https://www.bloomberg.com/markets/rates-bonds
B31: https://www.bloomberg.com/markets/rates-bonds | C31: RF | P31: =Q24 -> 0.038349302 | Q31: =Q25 -> Beta1
B32: https://www.nseindia.com/reports-indices-historical-index-data | C32: =C18 -> Nifty 50 | D32: 10Years | P32: =G22 -> 0.12227899 | Q32: Rm
B33: https://www.nseindia.com/report-detail/eq_security | C33: =L19 -> HDIL | D33: 10Years
P34: ER | Q34: =P30+P31*(P32-P30) -> 0.066042628 | R34: CAPM
B36: Working Note No .2 Kd
C38: Cost of Debt | G38: Calculation oF Interest
C40: Pre-Tax Cost of Debt | F40: =I40 -> 0 | H40: Interest | I40: =IFERROR('[1]Data Sheet'!K2,0) -> 0
C41: Tax | F41: =F12 -> 0.3
C42: After Tax Cost Debt | F42: =F40*(1-F41) -> 0

Sheet wc
B1: JSW STEEL LIMITED
B2: Working Capital Management
F3: DAYS
E4: =INDEX(H5:H8,MATCH(F4,I5:I8,0)) -> MONTH | F4: 30 | I4: DAYS
B5: Particulars | C5: FY 2024-25 | D5: FY 2023-24 | H5: MONTH | I5: 30
B6: Revenue from Operations | C6: =IFERROR('Profit & Loss'!D5,0) -> 3395.61 | D6: =IFERROR('Profit & Loss'!E5,0) -> 204.59 | H6: QTY | I6: 90
B7: COGS | C7: =-IFERROR((C32+C33)*-1,0) -> 27273 | D7: =-IFERROR((D32+D33)*-1,0) -> -7620 | H7: Half-yearly | I7: 180 | J7: COGS=Changes in Inventory+Employee Benefits+Other Expenses
B8: Cash & Cash Equivalents | C8: =IFERROR(SUM('Balance Sheet'!D14:D15),0) -> 1650.57 | D8: =IFERROR(SUM('Balance Sheet'!E14:E15),0) -> 1701.75 | H8: Yearly | I8: 360
B9: Inventories | C9: =IFERROR('Balance Sheet'!D11,0) -> 281468.68 | D9: =IFERROR('Balance Sheet'!E11,0) -> 283744.04
B10: Trade Receivables | C10: =IFERROR('Balance Sheet'!D13,0) -> 40633.99 | D10: =IFERROR('Balance Sheet'!E13,0) -> 39871.23
B11: Trade Payables | C11: =IFERROR('Balance Sheet'!D30,0) -> 41840.14 | D11: =IFERROR('Balance Sheet'!E30,0) -> 41749.35
B13: Days Sales Outstanding (DSO) | C13: =IFERROR((C10/C6)*$F$4,0) -> 358.99874 | D13: =IFERROR((D10/D6)*$F$4,0) -> 5846.5072
B14: Days Payable Outstanding (DPO) | C14: =IFERROR((C11/C6)*$F$4,0) -> 369.655 | D14: =IFERROR((D11/D6)*$F$4,0) -> 6121.9048
B15: Inventory Turnover (Days) | C15: =IFERROR((C9/C7)*$F$4,0) -> 309.61245 | D15: =IFERROR((D9/D7)*$F$4,0) -> -1117.1025
B17: Working Capital working Note no.1
B18: Calculate Working Capital | C18: =IFERROR(SUM(C8:C10)-C11,0) -> 281913.1 | D18: =IFERROR(SUM(D8:D10)-D11,0) -> 283567.67 | F18: Working Capital = Current Assets – Current Liabilities
F19: only consider the cash trade receivables and trde payables
B29: Expense Head | C29: Year 1 | D29: Year 2
B30: Cost of Materials Consumed | C30: 0 | D30: 0
B31: Purchase of Stock-in-Trade | C31: 0 | D31: 0
B32: Operating & Direct Expenses | C32: 22062 | D32: 42309
B33: Changes in Inventories | C33: 5211 | D33: -49929
B34: Employee Benefit Expenses | C34: 2294 | D34: 3160
B35: Finance Costs | C35: 28063 | D35: 34918
B36: Depreciation & Amortisation | C36: 541 | D36: 683
B37: Other Expenses | C37: 2363 | D37: 2977
B38: SOURCE : money control.com for this calculation only
