Workbook

Sheet Standalone Balance Sheet
A1: JSW STEEL LIMITED – STANDALONE BALANCE SHEET
A2: As at 31 March 2025 | (₹ in Crores)
A3: Particulars | B3: FY 2024-25 | C3: FY 2023-24
A4: I. ASSETS
A5: Non-Current Assets
A6: Property, Plant & Equipment | B6: 73322 | C6: 74457
A7: Capital Work-in-Progress | B7: 10538 | C7: 10504
A8: Right-of-Use Assets | B8: 2931 | C8: 2786
A9: Goodwill | B9: 413 | C9: 413
A10: Intangible Assets | B10: 1843 | C10: 1930
A11: Intangible Assets under Development | B11: 377 | C11: 352
A12: Investments in Subsidiaries, Associates & JVs | B12: 28483 | C12: 25195
A13: Investments (Non-current) | B13: 5040 | C13: 4946
A14: Loans (Non-current) | B14: 9710 | C14: 11501
A15: Derivative Assets (Non-current) | B15: 116 | C15: 88
A16: Other Financial Assets (Non-current) | B16: 6827 | C16: 5618
A17: Current Tax Assets (Net) | B17: 558 | C17: 781
A18: Other Non-Current Assets | B18: 5759 | C18: 3773
A19: Total Non-Current Assets | B19: =SUM(B5:B18) -> 145917 | C19: =SUM(C5:C18) -> 142344
A20: Current Assets
A21: Inventories | B21: 19819 | C21: 23234
A22: Investments (Current) | B22: 5816 | C22: 0
A23: Trade Receivables | B23: 5672 | C23: 6498
A24: Cash & Cash Equivalents | B24: 9595 | C24: 4953
A25: Bank Balances (other than above) | B25: 666 | C25: 3176
A26: Loans (Current) | B26: 0 | C26: 4
A27: Derivative Assets (Current) | B27: 232 | C27: 148
A28: Other Financial Assets (Current) | B28: 818 | C28: 1501
A29: Other Current Assets | B29: 3726 | C29: 3580
A30: Total Current Assets | B30: =SUM(B21:B29) -> 46344 | C30: =SUM(C21:C29) -> 43094
A31: TOTAL ASSETS | B31: =B19+B30 -> 192261 | C31: =C19+C30 -> 185438
A33: II. EQUITY AND LIABILITIES
A34: Equity
A35: Equity Share Capital | B35: 305 | C35: 305
A36: Other Equity | B36: 79534 | C36: 74978
A37: Total Equity | B37: =SUM(B35:B36) -> 79839 | C37: =SUM(C35:C36) -> 75283
A38: Non-Current Liabilities
A39: Borrowings (Non-current) | B39: 55919 | C39: 47241
A40: Lease Liabilities (Non-current) | B40: 2428 | C40: 1974
A41: Derivative Liabilities (Non-current) | B41: 0 | C41: 10
...

Sheet Standalone Income Statement
A1: JSW STEEL LIMITED – STANDALONE STATEMENT OF PROFIT & LOSS
A2: For the Year Ended 31 March 2025 | (₹ in Crores)
A3: Particulars | B3: FY 2024-25 | C3: FY 2023-24
A4: INCOME
A5: Revenue from Operations | B5: 127702 | C5: 135180
A6: Other Income | B6: 1865 | C6: 1704
A7: III. Total Income | B7: =B5+B6 -> 129567 | C7: =C5+C6 -> 136884
A9: EXPENSES
A10: Cost of Materials Consumed | B10: 65779 | C10: 72337
A11: Purchases of Stock-in-Trade | B11: 873 | C11: 363
A12: Changes in Inventories of FG, WIP & Stock-in-Trade | B12: 916 | C12: -1736
A13: Mining Premium and Royalties | B13: 9144 | C13: 10011
A14: Employee Benefits Expense | B14: 2488 | C14: 2357
A15: Finance Costs | B15: 6486 | C15: 6108
A16: Depreciation & Amortisation Expense | B16: 5913 | C16: 5435
A17: Other Expenses | B17: 30121 | C17: 29868
A18: IV. Total Expenses | B18: =SUM(B10:B17) -> 121720 | C18: =SUM(C10:C17) -> 124743
A20: V. Profit Before Exceptional Items & Tax | B20: =B7-B18 -> 7847 | C20: =C7-C18 -> 12141
A21: VI. Exceptional Items | B21: 1304 | C21: 39
A22: VII. Profit Before Tax (PBT) | B22: =B20-B21 -> 6543 | C22: =C20-C21 -> 12102
A24: TAX EXPENSE
A25: Current Tax | B25: 1729 | C25: 2422
A26: Deferred Tax | B26: -805 | C26: 608
A27: Tax Impact for Earlier Years | B27: -218 | C27: 1031
A28: VIII. Total Tax Expense | B28: =B25+B26+B27 -> 706 | C28: =C25+C26+C27 -> 4061
A30: IX. Profit for the Year (PAT) | B30: =B22-B28 -> 5837 | C30: =C22-C28 -> 8041
A32: OTHER COMPREHENSIVE INCOME (OCI)
A33: Re-measurements of Defined Benefit Plans | B33: 3 | C33: 0
A34: Equity Instruments through OCI | B34: 77 | C34: 2460
A35: Effective Portion of Gains/(Loss) on Hedging Instruments | B35: 555 | C35: -248
A36: Income Tax on OCI Items | B36: -264 | C36: -315
A37: X. Total Other Comprehensive Income | B37: =SUM(B33:B36) -> 371 | C37: =SUM(C33:C36) -> 1897
A39: XI. Total Comprehensive Income | B39: =B30+B37 -> 6208 | C39: =C30+C37 -> 9938
A41: KEY RATIOS
A42: Basic EPS (₹ per share of ₹1 each) | B42: 23.94 | C42: 33.16
A43: Diluted EPS (₹ per share of ₹1 each) | B43: 23.87 | C43: 33.01
A45: Source: JSW Steel Limited – Integrated Annual Report FY 2024-25, Page 219 (Standalone Financial Statements)

Sheet Consolidated Balance Sheet
A1: JSW STEEL LIMITED – CONSOLIDATED BALANCE SHEET
A2: As at 31 March 2025 | (₹ in Crores)
A3: Particulars | B3: FY 2024-25 | C3: FY 2023-24
A4: I. ASSETS
A5: Non-Current Assets
A6: Property, Plant & Equipment | B6: 116814 | C6: 105123
A7: Capital Work-in-Progress | B7: 20478 | C7: 29216
A8: Investment Property | B8: 163 | C8: 140
A9: Right-of-Use Assets | B9: 4837 | C9: 4477
A10: Goodwill | B10: 643 | C10: 639
A11: Other Intangible Assets | B11: 2009 | C11: 2082
A12: Intangible Assets under Development | B12: 529 | C12: 460
A13: Investments in JVs and Associates | B13: 3689 | C13: 1709
A14: Investments (Non-current) | B14: 5709 | C14: 5534
A15: Loans (Non-current) | B15: 70 | C15: 120
A16: Derivative Assets (Non-current) | B16: 116 | C16: 88
A17: Other Financial Assets (Non-current) | B17: 6899 | C17: 6135
... A20: Other Non-Current Assets | B20: 6924 | C20: 6603
A21: Total Non-Current Assets | B21: =SUM(B5:B20) -> 170006 | C21: =SUM(C5:C20) -> 163664
A22: Current Assets
A23: Inventories | B23: 34956 | C23: 37815
A24: Investments (Current) | B24: 5819 | C24: 3
A25: Trade Receivables | B25: 8415 | C25: 7548
A26: Cash & Cash Equivalents | B26: 11655 | C26: 8030
A27: Bank Balances (other than above) | B27: 1630 | C27: 4318
A28: Loans (Current) | B28: 2 | C28: 4
A29: Derivative Assets (Current) | B29: 284 | C29: 173
A30: Other Financial Assets (Current) | B30: 1247 | C30: 1752
A31: Current Tax Assets (Current) | B31: 15 | C31: 5
A32: Other Current Assets | B32: 6684 | C32: 4885
A33: Assets Held for Sale | B33: 1 | C33: 0
A34: Total Current Assets | B34: =SUM(B23:B33) -> 70708 | C34: =SUM(C23:C33) -> 64533
A35: TOTAL ASSETS | B35: =B21+B34 -> 240714 | C35: =C21+C34 -> 228197
A37: II. EQUITY AND LIABILITIES
A38: Equity
A39: Equity Share Capital | B39: 305 | C39: 305
A40: Other Equity (attributable to owners) | B40: 79191 | C40: 77364
A41: Non-Controlling Interests (NCI) | B41: 2170 | C41: 2107
A42: Total Equity | B42: =SUM(B39:B41) -> 81666 | C42: =SUM(C39:C41) -> 79776
A43: Non-Current Liabilities
...

Sheet Consolidated Income Statement
A1: JSW STEEL LIMITED – CONSOLIDATED STATEMENT OF PROFIT & LOSS
A2: For the Year Ended 31 March 2025 | (₹ in Crores)
A3: Particulars | B3: FY 2024-25 | C3: FY 2023-24
A4: INCOME
A5: I. Revenue from Operations | B5: 168824 | C5: 175006
A6: II. Other Income | B6: 694 | C6: 1004
A7: III. Total Income | B7: =B5+B6 -> 169518 | C7: =C5+C6 -> 176010
A9: EXPENSES
A10: Cost of Materials Consumed | B10: 88324 | C10: 93590
A11: Purchases of Stock-in-Trade | B11: 845 | C11: 1164
A12: Changes in Inventories of FG, WIP & Stock-in-Trade | B12: 829 | C12: -3087
A13: Mining Premium and Royalties | B13: 9144 | C13: 10011
A14: Employee Benefits Expense | B14: 4798 | C14: 4591
A15: Finance Cost | B15: 8412 | C15: 8105
A16: Depreciation & Amortisation Expense | B16: 9309 | C16: 8172
A17: Other Expenses | B17: 41980 | C17: 40501
A18: IV. Total Expenses | B18: =SUM(B10:B17) -> 163641 | C18: =SUM(C10:C17) -> 163047
A20: V. Profit Before Share of JV/Associates, Exceptional Items & Tax | B20: =B7-B18 -> 5877 | C20: =C7-C18 -> 12963
A21: VI. Share of Profit/(Loss) from JVs & Associates (Net) | B21: -311 | C21: -172
A22: VII. Profit Before Exceptional Items & Tax | B22: =B20+B21 -> 5566 | C22: =C20+C21 -> 12791
A23: VIII. Exceptional Items | B23: 489 | C23: -589
A24: IX. Profit Before Tax (PBT) | B24: =B22-B23 -> 5077 | C24: =C22-C23 -> 13380
A26: TAX EXPENSE
A27: Current Tax | B27: 1986 | C27: 2643
A28: Deferred Tax | B28: -182 | C28: 733
A29: Tax Impact of Earlier Years | B29: -218 | C29: 1031
A30: X. Total Tax Expense | B30: =B27+B28+B29 -> 1586 | C30: =C27+C28+C29 -> 4407
A32: XI. Net Profit for the Year (PAT) | B32: =B24-B30 -> 3491 | C32: =C24-C30 -> 8973
A34: PROFIT ATTRIBUTION
A35: Attributable to Owners of the Company | B35: 3504 | C35: 8812
A36: Attributable to Non-Controlling Interests | B36: -13 | C36: 161
A38: OTHER COMPREHENSIVE INCOME (OCI)
A39: Remeasurement Gain/(Loss) – Defined Benefit Plans | B39: 43 | C39: 4
A40: Net Gain/(Loss) on Equity Instruments through OCI | B40: 88 | C40: 2929
A41: Effective Portion of Gain/(Loss) on Hedging Instruments | B41: 551 | C41: -427
A42: Exchange Differences on Foreign Operations | B42: -303 | C42: -122
A43: Income Tax on OCI Items | B43: -286 | C43: -307
A44: XII. Total Other Comprehensive Income | B44: =SUM(B39:B43) -> 93 | C44: =SUM(C39:C43) -> 2077
A46: XIII. Total Comprehensive Income | B46: =B32+B44 -> 3584 | C46: =C32+C44 -> 11050
A48: KEY RATIOS
...

Sheet Cash Flow Statment
A1: JSW STEEL LIMITED
A2: CONSOLIDATED STATEMENT OF CASH FLOWS
A3: For the year ended 31 March 2025 | (₹ in crores) | Prepared using Indirect Method as per Ind AS 7
A4: Sr No | B4: Section | C4: Particulars | D4: FY 2024-25 (₹ Cr) | E4: FY 2023-24 (₹ Cr) | F4: YoY Change (₹ Cr)
C5: A. CASH FLOW FROM OPERATING ACTIVITIES
A6: 1 | B6: A | C6: Profit before tax | D6: 5077 | E6: 13380 | F6: -8303
A7: 2 | B7: A | C7: Adjustments for:
A8: 3 | B8: A | C8: Depreciation and amortisation expenses | D8: 9309 | E8: 8172 | F8: 1137
A9: 4 | B9: A | C9: Loss on sale of property, plant and equipment (net) | D9: 132 | E9: 93 | F9: 39
A10: 5 | B10: A | C10: Gain on sale of financial investments designated as FVTPL | D10: -24 | E10: -48 | F10: 24
A11: 6 | B11: A | C11: Export obligation deferred income amortisation | D11: -34 | E11: -129 | F11: 95
A12: 7 | B12: A | C12: Interest income | D12: -547 | E12: -786 | F12: 239
A13: 8 | B13: A | C13: Dividend income | D13: -24 | E13: -21 | F13: -3
A14: 9 | B14: A | C14: Interest expense | D14: 8125 | E14: 8051 | F14: 74
A15: 10 | B15: A | C15: Unrealised exchange (gain) / loss (net) | D15: 584 | E15: -10 | F15: 594
A16: 11 | B16: A | C16: Gain on financial instruments designated as FVTPL | D16: -23 | E16: -5 | F16: -18
A17: 12 | B17: A | C17: Unwinding of interest on financial assets carried at amortised cost | D17: -3 | E17: -40 | F17: 37
A18: 13 | B18: A | C18: Share based payment expense | D18: 170 | E18: 208 | F18: -38
A19: 14 | B19: A | C19: Share of (profit) / loss from joint ventures and associates (net) | D19: 311 | E19: 172 | F19: 139
... A31: 26 | B31: A | C31: Net cashflow generated from operating activities (A) | D31: 20899 | E31: 12078 | F31: 8821
C32: B. CASH FLOW FROM INVESTING ACTIVITIES
A33: 27 | B33: B | C33: Purchases of property, plant & equipment and intangible assets (incl. under development and capital advances) | D33: -12694 | E33: -15801 | F33: 3107
A34: 28 | B34: B | C34: Proceeds from sale of property, plant & equipment and intangible asset | D34: 59 | E34: 254 | F34: -195
A35: 29 | B35: B | C35: Cash flow on acquisition / disposal of subsidiaries (Net) | D35: - | E35: -630
A36: 30 | B36: B | C36: Investment in joint ventures and associates | D36: -1880 | E36: -396 | F36: -1484
A37: 31 | B37: B | C37: Equity investment in other related parties / others | D37: -78 | E37: -
A38: 32 | B38: B | C38: Loans repaid by related parties | D38: 50 | E38: -
A39: 33 | B39: B | C39: Purchase of current investments | D39: -12049 | E39: -3584 | F39: -8465
A40: 34 | B40: B | C40: Sale of current investments | D40: 6274 | E40: 3635 | F40: 2639
A41: 35 | B41: B | C41: Bank deposits not considered as cash and cash equivalents (net) | D41: 2637 | E41: 964 | F41: 1673
A42: 36 | B42: B | C42: Interest received | D42: 660 | E42: 899 | F42: -239
A43: 37 | B43: B | C43: Dividend received | D43: 24 | E43: 21 | F43: 3
A44: 38 | B44: B | C44: Net cash used in investing activities (B) | D44: -16997 | E44: -14638 | F44: -2359
C45: C. CASH FLOW FROM FINANCING ACTIVITIES
A46: 39 | B46: C | C46: Proceeds from sale of treasury shares | D46: -44 | E46: 6 | F46: -50
A47: 40 | B47: C | C47: Proceeds from non-current borrowings | D47: 28243 | E47: 19891 | F47: 8352
A48: 41 | B48: C | C48: Repayment of non-current borrowings | D48: -16697 | E48: -16328 | F48: -369
A49: 42 | B49: C | C49: Proceeds from / (repayment of) current borrowings (net) | D49: -2061 | E49: 967 | F49: -3028
A50: 43 | B50: C | C50: Repayment of lease liabilities | D50: -369 | E50: -632 | F50: 263
A51: 44 | B51: C | C51: Interest paid | D51: -8835 | E51: -8087 | F51: -748
...

Sheet WACC
B2: JSW STEEL LIMITED
B4: As at 31 March 2025 | (₹ in Crores)
B5: Wegithr Average Cost Of Capital
B7: All Figure are in INR unless Stated Otherwise
K9: Weighted Average Cost of Capital
G10: Equity / | H10: Debt/ | I10: Cost of | J10: Cost of
B11: Name oF Company | C11: Country | D11: Total Equity | E11: Total Debt | F11: Tax Rate 1 | G11: Weights | H11: Weights | I11: Equity | J11: Debt | K11: Cost of Equity | N11: =I12 -> 0.096282484
B12: JSW STEEL LIMITED | C12: Iindia | D12: =IFERROR(SUM('Consolidated Balance Sheet'!B39:B40),0) -> 79496 | E12: =IFERROR(SUM('Consolidated Balance Sheet'!B44,'Consolidated Balance Sheet'!B45,'Consolidated Balance Sheet'!B53,'Consolidated Balance Sheet'!B54),0) -> 98752 | F12: 0.3 | G12: =IFERROR(D12/SUM(D12:E12),0) -> 0.44598537 | H12: =IFERROR(E12/(SUM(D12:E12)),0) -> 0.55401463 | I12: =C39 -> 0.096282484 | J12: =M25 -> 0.059628159 | K12: Equity Weight | N12: =G12 -> 0.44598537
K13: Cost of Debt | N13: =J12 -> 0.059628159
B14: Total Capital | D14: =SUM(D12:E12) -> 178248 | K14: Debt Weight | N14: =H12 -> 0.55401463
K15: WACC | N15: =(N11*N12)+(N13*N14) -> 0.075975452
B18: Working Notes -No.1
B19: JSW STEEL LIMITED Dividends | I19: Working Note No .2 Kd
B21: Announcement Date | C21: Ex-Dividend Date | D21: Dividend Type | E21: Dividend (Rs) | F21: Yearly Growth rate | J21: Cost of Debt | N21: Calculation oF Interest
B22: 18 May, 2016 | C22: 04 Jul, 2016 | D22: Final | E22: 7.5
B23: 18 May, 2017 | C23: 12 Jun, 2017 | D23: Final | E23: 2.25 | F23: =E23/E22-1 -> -0.7 | J23: Pre-Tax Cost of Debt | M23: =P23 -> 0.085183085 | O23: Interest | P23: =IFERROR(SUM('Consolidated Income Statement'!B$15)/WACC!E$12,0) -> 0.085183085
B24: 16 May, 2018 | C24: 06 Jul, 2018 | D24: Final | E24: 3.2 | F24: =E24/E23-1 -> 0.42222222 | J24: Tax | M24: =F12 -> 0.3
B25: 24 May, 2019 | C25: 08 Jul, 2019 | D25: Final | E25: 4.1 | F25: =E25/E24-1 -> 0.28125 | J25: After Tax Cost Debt | M25: =M23*(1-M24) -> 0.059628159
B26: 22 May, 2020 | C26: 06 Jul, 2020 | D26: Final | E26: 2 | F26: =E26/E25-1 -> -0.51219512
B27: 21 May, 2021 | C27: 05 Jul, 2021 | D27: Final | E27: 6.5 | F27: =E27/E26-1 -> 2.25 | J27: Total Debt = Borrowings + Lease Liabilities
B28: 27 May, 2022 | C28: 04 Jul, 2022 | D28: Final | E28: 17.35 | F28: =E28/E27-1 -> 1.6692308
B29: 22 May, 2023 | C29: 11 Jul, 2023 | D29: Final | E29: 3.4 | F29: =E29/E28-1 -> -0.80403458
B30: 21 May, 2024 | C30: 09 Jul, 2024 | D30: Final | E30: 7.3 | F30: =E30/E29-1 -> 1.1470588
B31: 23 May, 2025 | C31: 08 Jul, 2025 | D31: Final | E31: 2.8 | F31: =E31/E30-1 -> -0.61643836
B33: SOURCE:https://www.moneycontrol.com/company-facts/jswsteel/dividends/JSW01/ | E33: Avearge Growth | F33: =AVERAGE(F22:F30) -> 0.46919151
B34: SOURCE :https://www.nseindia.com/get-quote/equity/JSWSTEEL/JSW-Steel-Limited | E34: CAGR | F34: =_xlfn.RRI(10,E22,E31) -> -0.093830007 | G34: 0.0938
E35: Median | F35: =MEDIAN(F22:F30) -> 0.35173611
E36: Market Price | F36: 1233.7 | G36: Taken From Nse
B37: Working Note.1(a)
B38: D1 | C38: =IFERROR(E31*(1+G34),0) -> 3.06264
B39: Ke | C39: =IFERROR((C38/F36)+G34,0) -> 0.096282484

Sheet Working Capital Management
B1: JSW STEEL LIMITED
B2: Working Capital Management
F3: DAYS
E4: =INDEX(H5:H8,MATCH(F4,I5:I8,0)) -> Yearly | F4: 360 | I4: DAYS
B5: Particulars | C5: FY 2024-25 | D5: FY 2023-24 | H5: MONTH | I5: 30
B6: Revenue from Operations | C6: =IFERROR('Consolidated Income Statement'!B5,0) -> 168824 | D6: =IFERROR('Consolidated Income Statement'!C5,0) -> 175006 | H6: QTY | I6: 90
B7: COGS | C7: =-IFERROR(('Consolidated Income Statement'!B18-SUM('Consolidated Income Statement'!B14:B17))*-1,0) -> 99142 | D7: =-IFERROR(('Consolidated Income Statement'!C18-SUM('Consolidated Income Statement'!C14:C17))*-1,0) -> 101678 | H7: Half-yearly | I7: 180
B8: Cash & Cash Equivalents | C8: =IFERROR('Consolidated Balance Sheet'!B26,0) -> 11655 | D8: =IFERROR('Consolidated Balance Sheet'!C26,0) -> 8030 | H8: Yearly | I8: 360
B9: Inventories | C9: =IFERROR('Consolidated Balance Sheet'!B23,0) -> 34956 | D9: =IFERROR('Consolidated Balance Sheet'!C23,0) -> 37815
B10: Trade Receivables | C10: =IFERROR('Consolidated Balance Sheet'!B25,0) -> 8415 | D10: =IFERROR('Consolidated Balance Sheet'!C25,0) -> 7548
B11: Trade Payables | C11: =IFERROR(SUM('Consolidated Balance Sheet'!B56,'Consolidated Balance Sheet'!B57),0) -> 12018 | D11: =IFERROR(SUM('Consolidated Balance Sheet'!C56,'Consolidated Balance Sheet'!C57),0) -> 15711
B13: Days Sales Outstanding (DSO) | C13: =IFERROR((C10/C6)*$F$4,0) -> 17.944131 | D13: =IFERROR((D10/D6)*$F$4,0) -> 15.526782
B14: Days Payable Outstanding (DPO) | C14: =IFERROR((C11/C6)*$F$4,0) -> 25.627162 | D14: =IFERROR((D11/D6)*$F$4,0) -> 32.318663
B15: Inventory Turnover (Days) | C15: =IFERROR((C9/C7)*$F$4,0) -> 126.93067 | D15: =IFERROR((D9/D7)*$F$4,0) -> 133.88737
B17: Working Capital working Note no.1
B18: Calculate Working Capital | C18: =IFERROR(SUM(C8:C10)-C11,0) -> 43008 | D18: =IFERROR(SUM(D8:D10)-D11,0) -> 37682 | F18: Working Capital = Current Assets – Current Liabilities
F19: only consider the cash trade receivables and trde payables
B22: ANALYSIS
B23: DSO(SHOWCUSTOMERS DELAY IN PAYMENT THIS WILL REDUCED LIQUIDITY AND ALSO IIMPCT ON THE WORKING CAPITAL LIKE BAD DEBTS , SHORT TERM BORROWINGS USE BY FIRMS
B24: DPO( COMPANY PAY ITS SUPPLIER QUICKELY AND ALSO SHOW STRONG RELATION SHIP WITH SUPPLIER BUT THIS IMPACT LIQUIDITY
B25: INVENTORY DAYS (IS REDUCED THIS REPRESENT FAST COVERSION OF STOCK INTO SALES MEANS MORE ORDERS AND TO MAINTAIN THIS COMPANY NEED TIMELY RAW MATERIAL TO INCREASE PRODUCTION THAT’S WHAY DPO IS REDUCCED ANDN DSO IS INCREASED
B26: WORKING CAPITAL IS INCREASE SHOWING MORE LIQUDITY AND SUFFICIENT FUNDS TO MEET THEIR DAY TO DAY OBLIGATION/
B28: CONCLUSION: TTHIS ANALYSIS SHOW COMPANY WANT TO INCREASE TO THEIR CUSTOMER BASE AND REVENUE THIS ALSO REPRESENT IN THE DPO/ DSO PLOICIS OF THE MANAGEMENT
