Workbook

Sheet comps -raw
B2: Gems, Jewellery And Watches Companies
B3: 94 results found: Showing page 1 of 4
B4: Export
B5: Edit Columns
B6: S.No. | C6: Name | D6: CMP Rs. | E6: Mar Cap Rs.Cr. | F6: Debt Rs.Cr. | G6: Debt / Eq
B7: 1 | C7: Titan Company | D7: 3953.2 | E7: 350493.51 | F7: 12465 | G7: 0.97
B8: 2 | C8: Kalyan Jewellers | D8: 365.5 | E8: 37754.06 | F8: 5334.96 | G8: 1
B9: 3 | C9: Thangamayil Jew. | D9: 3218.9 | E9: 10008.14 | F9: 1124.35 | G9: 0.96
B10: 4 | C10: PC Jeweller | D10: 10.38 | E10: 8202.09 | F10: 1594.49 | G10: 0.22
B11: 55 | C11: SJ Corp | D11: 71.47 | E11: 59.71 | F11: 0 | G11: 0
B13: =B11 -> 55 | C13: =C11 -> SJ Corp | D13: =D11 -> 71.47 | E13: =E11 -> 59.71 | F13: =F11 -> 0 | G13: =G11 -> 0
B14: 41 | C14: Narbada Gems | D14: 59.25 | E14: 125.36 | F14: 28.57 | G14: 0.48
B15: 42 | C15: Moksh Ornaments | D15: 13.39 | E15: 118.17 | F15: 38.75 | G15: 0.31
B16: 57 | C16: Mishka Exim | D16: 40.9 | E16: 59.1 | F16: 1.23 | G16: 0.07
B17: 52 | C17: Bhakti Gems | D17: 43.13 | E17: 64.86 | F17: 0.81 | G17: 0.03

Sheet dccf
C8: Wegithr Average Cost Of Capital
C10: All Figure are in INR unless Stated Otherwise
C12: Peers Companies
H13: Debt/ | I13: Debt/ | J13: Levered | K13: Unlevered
C14: Name oF Company | D14: Country | E14: Total Debt | F14: Total Equity | G14: Tax Rate 1 | H14: Equity | I14: Equity | J14: Beta 2 | K14: Beta 3
C15: SJ Corp | D15: India | E15: ='comps -raw'!F13 -> 0 | F15: ='comps -raw'!E13 -> 59.71 | G15: 0.3 | H15: =IFERROR(E15/F15,0) -> 0 | I15: =IFERROR(E15/(SUM(E15:F15)),0) -> 0 | J15: ='beta sj corpoation'!L14 -> -0.1905929 | K15: =J15/(1+(1-G15)*H15) -> -0.1905929
C16: Narbada Gems | D16: India | E16: ='comps -raw'!F14 -> 28.57 | F16: ='comps -raw'!E14 -> 125.36 | G16: 0.3 | H16: =IFERROR(E16/F16,0) -> 0.22790364 | I16: =IFERROR(E16/(SUM(E16:F16)),0) -> 0.18560385 | J16: ='Narbada beta'!J21 -> 0.34097493 | K16: =J16/(1+(1-G16)*H16) -> 0.2940624
C17: Moksh Ornaments | D17: India | E17: ='comps -raw'!F15 -> 38.75 | F17: ='comps -raw'!E15 -> 118.17 | G17: 0.3 | H17: =IFERROR(E17/F17,0) -> 0.32791741 | I17: =IFERROR(E17/(SUM(E17:F17)),0) -> 0.24694112 | J17: ='Moksh BETA'!J15 -> 0.58487445 | K17: =J17/(1+(1-G17)*H17) -> 0.47568474
C18: Mishka Exim | D18: India | E18: ='comps -raw'!F16 -> 1.23 | F18: ='comps -raw'!E16 -> 59.1 | G18: 0.3 | H18: =IFERROR(E18/F18,0) -> 0.020812183 | I18: =IFERROR(E18/(SUM(E18:F18)),0) -> 0.020387867 | J18: ='Mishka Exim Ltd'!J15 -> 0.69271189 | K18: =J18/(1+(1-G18)*H18) -> 0.68276501
C19: Bhakti Gems | D19: India | E19: ='comps -raw'!F17 -> 0.81 | F19: ='comps -raw'!E17 -> 64.86 | G19: 0.3 | H19: =IFERROR(E19/F19,0) -> 0.012488437 | I19: =IFERROR(E19/(SUM(E19:F19)),0) -> 0.012334399 | J19: ='Guru BETA'!K21 -> 0.2245264 | K19: =J19/(1+(1-G19)*H19) -> 0.22258062
F22: Average | G22: =AVERAGE(G15:G19) -> 0.3 | H22: =AVERAGE(H15:H19) -> 0.11782433 | I22: =AVERAGE(I15:I19) -> 0.093053446 | J22: =AVERAGE(J15:J19) -> 0.33049895 | K22: =AVERAGE(K15:K19) -> 0.29689997
F23: Median | G23: =MEDIAN(G15:G19) -> 0.3 | H23: =MEDIAN(H15:H19) -> 0.020812183 | I23: =MEDIAN(I15:I19) -> 0.020387867 | J23: =MEDIAN(J15:J19) -> 0.34097493 | K23: =MEDIAN(K15:K19) -> 0.2940624
C27: Cost of Debt | H27: Cost Of Equity
C29: Pre-Tax Cost of Debt | F29: =IFERROR(120/E15,0) -> 0 | H29: Risk Free Rate | K29: 0.06695
C30: Tax | F30: =G16 -> 0.3 | H30: Equity Risk Premium | K30: ='market return'!U12-dccf!K29 -> 0.076354762
C31: After Tax Cost Debt | F31: =F29*(1-F30) -> 0 | H31: Levered Bta 4 | K31: =K40 -> 0.30122537
H32: Cost Of Equity | K32: =K29+K30*K31 -> 0.089949991
C35: Capital Structure | H35: Levered Beta
E37: Current | F37: Traget | H37: comps Median Unlevered Beta | K37: =K22 -> 0.29689997
C38: Total Debt | D38: =E15 -> 0 | E38: =H15 -> 0 | F38: =I23 -> 0.020387867 | H38: Traget Debt/Equity | K38: =F43 -> 0.020812183
C39: Market Capitaliziation | D39: =F15 -> 59.71 | E39: =D39/$D$40 -> 1 | F39: =F40-F38 -> 0.97961213 | H39: Tax Rate | K39: =G16 -> 0.3
C40: Total Capitalization | D40: =IFERROR(SUM(D38:D39),0) -> 59.71 | E40: =100% -> 1 | F40: =100% -> 1 | H40: levered Beta | K40: =K37*(1+(1-K39)*K38) -> 0.30122537
C43: Debt/Equity | E43: =IFERROR(E38/E39,0) -> 0 | F43: =IFERROR(F38/F39,0) -> 0.020812183 | H43: Weighted Average Cost of Capital
C45: 1. Tax Rate considered as Marginal Tax Rate for the country | H45: Cost of Equity | K45: =K32 -> 0.089949991
C46: 2. Levered Beta is based on 5 year monthly data | H46: Equity Weight | K46: =E39 -> 1
C47: 3. Unlevered Beta = Levered Beta/(1+(1-Tax Rate) x Debt/Equity)
C48: 4. Levered Beta = Unlevered Beta*(1+(1-Tax Rate) x Debt/Equity) | H48: Cost of Debt | K48: =F31 -> 0
H49: Debt Weight | K49: =F38 -> 0.020387867
H51: WACC | K51: =(K45*K46)+(K48*K49) -> 0.089949991

Sheet market return
B6: Return on market nifty 50 26 years | P6: 0.0763 | Q6: 5 YEAR AVERAGE
P7: Return on market Sensex last 21 years
B9: Year | C9: Annual | P9: 2026 | R9: -0.0224
B10: 2000 | C10: -0.1465 | E10: Average Return | G10: =AVERAGE(C10:C35) -> 0.15149231 | H10: =MEDIAN(C10:C35) -> 0.1135 | P10: 2025 | R10: 0.0906 | T10: Average return | U10: =AVERAGE(R9:R29) -> 0.14330476
B11: 2001 | C11: -0.1618 | E11: Dividevd yield | G11: 1.39% 1 | P11: 2024 | R11: 0.0817 | T11: Dividevd yield | U11: 1.15 1
B12: 2002 | C12: 0.0325 | E12: Total Market Return | G12: =SUM(G10:G11) -> 0.15149231 | P12: 2023 | R12: 0.1874 | T12: Total Market Return | U12: =SUM(U10:U11) -> 0.14330476
B13: 2003 | C13: 0.719 | P13: 2022 | R13: 0.0444
B14: 2004 | C14: 0.1068 | P14: 2021 | R14: 0.2199
B15: 2005 | C15: 0.3634 | P15: 2020 | R15: 0.1575
B16: 2006 | C16: 0.3983 | P16: 2019 | R16: 0.1438
B17: 2007 | C17: 0.5477 | P17: 2018 | R17: 0.0591
B18: 2008 | C18: -0.5179 | P18: 2017 | R18: 0.2791
B19: 2009 | C19: 0.7576 | P19: 2016 | R19: 0.0195
B20: 2010 | C20: 0.1795 | P20: 2015 | R20: -0.0503
B21: 2011 | C21: -0.2462 | P21: 2014 | R21: 0.2989
B22: 2012 | C22: 0.277 | P22: 2013 | R22: 0.0898
B23: 2013 | C23: 0.0676 | P23: 2012 | R23: 0.257
B24: 2014 | C24: 0.3139 | P24: 2011 | R24: -0.2464
... B29: 2019 | C29: 0.1202 | P29: 2006 | R29: 0.4682
B30: 2020 | C30: 0.149
B31: 2021 | C31: 0.2412
B32: 2022 | C32: 0.0432
B33: 2023 | C33: 0.1942
B34: 2024 | C34: 0.0875
B35: 2025 | C35: 0.1051

Sheet sp j corporation
B2: Date | C2: Adj Close | D2: Close | E2: Volume | F2: Close | G2: Date | H2: Adj Close | I2: Volume | J2: Close | M2: Date | N2: Adj Close | O2: Volume | P2: Open | Q2: High | R2: Low | S2: Close
B3: Jan 26 2026 | C3: 68.07 | D3: 6807 | E3: 1525 | F3: 6807 | G3: Jan 26 2026 | H3: 8226978 | I3: 97600 | J3: 8226978 | M3: 46048 | N3: 68.07 | O3: 1525 | P3: 65 | Q3: 68.07 | R3: 61.75 | S3: 68.07 | V3: Date
B4: Jan 19 2026 | C4: 65 | D4: 6500 | E4: - | F4: 6500 | G4: Jan 19 2026 | H4: 8153770 | I4: 86600 | J4: 8153770 | M4: 46041 | N4: 65 | O4: - | P4: 65 | Q4: 65 | R4: 65 | S4: 65
B5: Jan 12 2026 | C5: 65 | D5: 6500 | E5: - | F5: 6500 | G5: Jan 12 2026 | H5: 8357035 | I5: 60400 | J5: 8357035 | M5: 46034 | N5: 65 | O5: - | P5: 65 | Q5: 65 | R5: 65 | S5: 65 | V5: Price
B6: Jan 5 2026 | C6: 65 | D6: 6500 | E6: - | F6: 6500 | G6: Jan 5 2026 | H6: 8357624 | I6: 93900 | J6: 8357624 | M6: 46027 | N6: 65 | O6: - | P6: 65 | Q6: 65 | R6: 65 | S6: 65
B7: Dec 29 2025 | C7: 65 | D7: 6500 | E7: 150 | F7: 6500 | G7: Dec 29 2025 | H7: 8576201 | I7: 110300 | J7: 8576201 | M7: 46020 | N7: 65 | O7: 150 | P7: 65 | Q7: 65 | R7: 65 | S7: 65 | V7: Open
B8: Dec 22 2025 | C8: 65 | D8: 6500 | E8: - | F8: 6500 | G8: Dec 22 2025 | H8: 8504145 | I8: 25400 | J8: 8504145 | M8: 46013 | N8: 65 | O8: - | P8: 65 | Q8: 65 | R8: 65 | S8: 65
B9: Dec 15 2025 | C9: 65 | D9: 6500 | E9: - | F9: 6500 | G9: Dec 15 2025 | H9: 8492936 | I9: 54500 | J9: 8492936 | M9: 46006 | N9: 65 | O9: - | P9: 65 | Q9: 65 | R9: 65 | S9: 65 | V9: High
B10: Dec 8 2025 | C10: 65 | D10: 6500 | E10: - | F10: 6500 | G10: Dec 8 2025 | H10: 8526766 | I10: 52000 | J10: 8526766 | M10: 45999 | N10: 65 | O10: - | P10: 65 | Q10: 65 | R10: 65 | S10: 65
B11: Dec 1 2025 | C11: 65 | D11: 6500 | E11: - | F11: 6500 | G11: Dec 1 2025 | H11: 8571237 | I11: 57500 | J11: 8571237 | M11: 45992 | N11: 65 | O11: - | P11: 65 | Q11: 65 | R11: 65 | S11: 65 | V11: Low
B12: Nov 24 2025 | C12: 65 | D12: 6500 | E12: - | F12: 6500 | G12: Nov 24 2025 | H12: 8570667 | I12: 51800 | J12: 8570667 | M12: 45985 | N12: 65 | O12: - | P12: 65 | Q12: 65 | R12: 65 | S12: 65
B13: Nov 17 2025 | C13: 65 | D13: 6500 | E13: - | F13: 6500 | G13: Nov 17 2025 | H13: 8523192 | I13: 68600 | J13: 8523192 | M13: 45978 | N13: 65 | O13: - | P13: 65 | Q13: 65 | R13: 65 | S13: 65 | V13: Vol.
B14: Nov 10 2025 | C14: 65 | D14: 6500 | E14: - | F14: 6500 | G14: Nov 10 2025 | H14: 8456278 | I14: 71900 | J14: 8456278 | M14: 45971 | N14: 65 | O14: - | P14: 65 | Q14: 65 | R14: 65 | S14: 65
B15: Nov 3 2025 | C15: 65 | D15: 6500 | E15: - | F15: 6500 | G15: Nov 3 2025 | H15: 8321628 | I15: 44600 | J15: 8321628 | M15: 45964 | N15: 65 | O15: - | P15: 65 | Q15: 65 | R15: 65 | S15: 65 | V15: High | W15: =V5 -> Price | X15: Open | Y15: High | Z15: Low | AA15: =AA3 -> 0
B16: Oct 27 2025 | C16: 65 | D16: 6500 | E16: - | F16: 6500 | G16: Oct 27 2025 | H16: 8393871 | I16: 66000 | J16: 8393871 | M16: 45957 | N16: 65 | O16: - | P16: 65 | Q16: 65 | R16: 65 | S16: 65 | V16: 46024 | W16: 58.09 | X16: 55.62 | Y16: 60.2 | Z16: 55.62 | AA16: 6.62K | AB16: 0.0236
B17: Oct 20 2025 | C17: 65 | D17: 6500 | E17: 188 | F17: 6500 | G17: Oct 20 2025 | H17: 8421188 | I17: 53600 | J17: 8421188 | M17: 45950 | N17: 65 | O17: 188 | P17: 65.61 | Q17: 65.61 | R17: 65 | S17: 65 | V17: 25-01-2026 | W17: 56.75 | X17: 58.49 | Y17: 62.98 | Z17: 55.17 | AA17: 4.99K | AB17: -0.0249
B18: Oct 13 2025 | C18: 64.97 | D18: 6497 | E18: - | F18: 6497 | G18: Oct 13 2025 | H18: 8395219 | I18: 73900 | J18: 8395219 | M18: 45943 | N18: 64.97 | O18: - | P18: 64.97 | Q18: 64.97 | R18: 64.97 | S18: 64.97 | V18: 18-01-2026 | W18: 58.2 | X18: 61 | Y18: 63 | Z18: 56.1 | AA18: 4.78K | AB18: -0.0889
B19: Oct 6 2025 | C19: 64.97 | D19: 6497 | E19: - | F19: 6497 | G19: Oct 6 2025 | H19: 8250082 | I19: 74800 | J19: 8250082 | M19: 45936 | N19: 64.97 | O19: - | P19: 64.97 | Q19: 64.97 | R19: 64.97 | S19: 64.97 | V19: 46327 | W19: 63.88 | X19: 64.18 | Y19: 64.5 | Z19: 59.23 | AA19: 4.48K | AB19: -0.0047
B20: Sep 29 2025 | C20: 64.97 | D20: 6497 | E20: - | F20: 6497 | G20: Sep 29 2025 | H20: 8120717 | I20: 51600 | J20: 8120717 | M20: 45929 | N20: 64.97 | O20: - | P20: 64.97 | Q20: 64.97 | R20: 64.97 | S20: 64.97 | V20: 46113 | W20: 64.18 | X20: 65.7 | Y20: 69.5 | Z20: 61 | AA20: 12.01K | AB20: 0.0134
B21: Sep 22 2025 | C21: 64.97 | D21: 6497 | E21: - | F21: 6497 | G21: Sep 22 2025 | H21: 8042646 | I21: 60200 | J21: 8042646 | M21: 45922 | N21: 64.97 | O21: - | P21: 64.97 | Q21: 64.97 | R21: 64.97 | S21: 64.97 | V21: 28-12-2025 | W21: 63.33 | X21: 67 | Y21: 67 | Z21: 57 | AA21: 4.86K | AB21: -0.0861
B22: Sep 15 2025 | C22: 64.97 | D22: 6497 | E22: - | F22: 6497 | G22: Sep 15 2025 | H22: 8262623 | I22: 57600 | J22: 8262623 | M22: 45915 | N22: 64.97 | O22: - | P22: 64.97 | Q22: 64.97 | R22: 64.97 | S22: 64.97 | V22: 21-12-2025 | W22: 69.3 | X22: 64.98 | Y22: 69.5 | Z22: 59.72 | AA22: 0.67K | AB22: 0.0869
B23: Sep 8 2025 | C23: 64.97 | D23: 6497 | E23: - | F23: 6497 | G23: Sep 8 2025 | H23: 8190470 | I23: 51400 | J23: 8190470 | M23: 45908 | N23: 64.97 | O23: - | P23: 64.97 | Q23: 64.97 | R23: 64.97 | S23: 64.97 | V23: 14-12-2025 | W23: 63.76 | X23: 65.01 | Y23: 70 | Z23: 57.2 | AA23: 4.38K | AB23: -0.0558
B24: Sep 1 2025 | C24: 64.97 | D24: 6497 | E24: - | F24: 6497 | G24: Sep 1 2025 | H24: 8071076 | I24: 56500 | J24: 8071076 | M24: 45901 | N24: 64.97 | O24: - | P24: 64.97 | Q24: 64.97 | R24: 64.97 | S24: 64.97 | V24: 45850 | W24: 67.53 | X24: 69.39 | Y24: 70.5 | Z24: 64.3 | AA24: 0.57K | AB24: -0.0268
B25: Aug 25 2025 | C25: 64.97 | D25: 6497 | E25: 1 | F25: 6497 | G25: Aug 25 2025 | H25: 7980965 | I25: 50500 | J25: 7980965 | M25: 45894 | N25: 64.97 | O25: 1 | P25: 64.97 | Q25: 64.97 | R25: 64.97 | S25: 64.97 | V25: 30-11-2025 | W25: 69.39 | X25: 73.98 | Y25: 73.98 | Z25: 65.35 | AA25: 1.77K | AB25: 0.0114
B26: Aug 18 2025 | C26: 58.94 | D26: 5894 | E26: - | F26: 5894 | G26: Aug 18 2025 | H26: 8130685 | I26: 56400 | J26: 8130685 | M26: 45887 | N26: 58.94 | O26: - | P26: 58.94 | Q26: 58.94 | R26: 58.94 | S26: 58.94 | V26: 23-11-2025 | W26: 68.61 | X26: 66 | Y26: 69.4 | Z26: 66 | AA26: 6.69K | AB26: -0.0055 | AE26: sensex x inest doc, com
B27: Aug 11 2025 | C27: 58.94 | D27: 5894 | E27: - | F27: 5894 | G27: Aug 11 2025 | H27: 8059766 | I27: 38400 | J27: 8059766 | M27: 45880 | N27: 58.94 | O27: - | P27: 58.94 | Q27: 58.94 | R27: 58.94 | S27: 58.94 | V27: 16-11-2025 | W27: 68.99 | X27: 74 | Y27: 77 | Z27: 68.5 | AA27: 14.05K | AB27: -0.0589
B28: Aug 4 2025 | C28: 58.94 | D28: 5894 | E28: - | F28: 5894 | G28: Aug 4 2025 | H28: 7985779 | I28: 86800 | J28: 7985779 | M28: 45873 | N28: 58.94 | O28: - | P28: 58.94 | Q28: 58.94 | R28: 58.94 | S28: 58.94 | V28: 45911 | W28: 73.31 | X28: 70.46 | Y28: 75 | Z28: 67.51 | AA28: 10.18K | AB28: 0.0615
B29: Jul 28 2025 | C29: 58.94 | D29: 5894 | E29: - | F29: 5894 | G29: Jul 28 2025 | H29: 8059991 | I29: 49000 | J29: 8059991 | M29: 45866 | N29: 58.94 | O29: - | P29: 58.94 | Q29: 58.94 | R29: 58.94 | S29: 58.94 | V29: 45699 | W29: 69.06 | X29: 70.05 | Y29: 74.9 | Z29: 66.52 | AA29: 11.22K | AB29: -0.0537 | AE29: Date | AF29: Price | AG29: Price | AH29: Price | AI29: Price
B30: Jul 21 2025 | C30: 58.94 | D30: 5894 | E30: - | F30: 5894 | G30: Jul 21 2025 | H30: 8146309 | I30: 73300 | J30: 8146309 | M30: 45859 | N30: 58.94 | O30: - | P30: 58.94 | Q30: 58.94 | R30: 58.94 | S30: 58.94 | V30: 26-10-2025 | W30: 72.98 | X30: 75 | Y30: 77 | Z30: 68.4 | AA30: 10.08K | AB30: 0.0039 | AE30: 46024 | AF30: 83817.69 | AG30: 82388.97 | AH30: 85871.73 | AI30: 79899.42 | AJ30: 72.45M | AK30: 0.0188 | AM30: Date | AO30: Open | AP30: High | AQ30: Low | AV30: Open | AW30: High | AX30: Low | BD30: Open | BE30: High | BF30: Low
B31: Jul 14 2025 | C31: 58.94 | D31: 5894 | E31: 20 | F31: 5894 | G31: Jul 14 2025 | H31: 8175773 | I31: 52700 | J31: 8175773 | M31: 45852 | N31: 58.94 | O31: 20 | P31: 56.14 | Q31: 58.94 | R31: 56.14 | S31: 58.94 | V31: 19-10-2025 | W31: 72.7 | X31: 69.95 | Y31: 75.8 | Z31: 68 | AA31: 4.71K | AB31: 0.0393 | AE31: 25-01-2026 | AF31: 82269.78 | AG31: 81436.79 | AH31: 82689.96 | AI31: 81088.59 | AJ31: 97.65M | AK31: 0.009 | AM31: 46024 | AN31: 13.39 | AO31: 13.41 | AP31: 14.3 | AQ31: 13 | AR31: 440.62K | AS31: -0.0262 | AU31: 46024 | AV31: 40.9 | AW31: 41.51 | AX31: 43.15 | AY31: 40.9 | AZ31: 14.46K | BA31: 0.0049 | BC31: 46024 | BD31: 43.13 | BE31: 41.2 | BF31: 44.98 | BG31: 39.5 | BH31: 419.09K | BI31: 0.0403
B32: Jul 7 2025 | C32: 56.14 | D32: 5614 | E32: - | F32: 5614 | G32: Jul 7 2025 | H32: 8250047 | I32: 47500 | J32: 8250047 | M32: 45845 | N32: 56.14 | O32: - | P32: 56.14 | Q32: 56.14 | R32: 56.14 | S32: 56.14 | V32: 46001 | W32: 69.95 | X32: 72.41 | Y32: 72.41 | Z32: 67.5 | AA32: 12.38K | AB32: -0.0388 | AE32: 18-01-2026 | AF32: 81537.7 | AG32: 83494.49 | AH32: 83539.93 | AI32: 81124.45 | AJ32: 86.59M | AK32: -0.0243 | AM32: 25-01-2026 | AN32: 13.75 | AO32: 14.15 | AP32: 14.49 | AQ32: 13.51 | AR32: 572.54K | AS32: -0.0337 | AU32: 25-01-2026 | AV32: 40.7 | AW32: 43.95 | AX32: 44.2 | AY32: 40.1 | AZ32: 8.28K | BA32: -0.0739 | BC32: 25-01-2026 | BD32: 41.46 | BE32: 44.49 | BF32: 44.49 | BG32: 40 | BH32: 273.48K | BI32: -0.0473
B33: Jun 30 2025 | C33: 56.14 | D33: 5614 | E33: - | F33: 5614 | G33: Jun 30 2025 | H33: 8343289 | I33: 54300 | J33: 8343289 | M33: 45838 | N33: 56.14 | O33: - | P33: 56.14 | Q33: 56.14 | R33: 56.14 | S33: 56.14 | V33: 45787 | W33: 72.77 | X33: 71 | Y33: 77 | Z33: 66.54 | AA33: 20.12K | AB33: 0.0452 | AE33: 46327 | AF33: 83570.35 | AG33: 83435.31 | AH33: 84258.03 | AI33: 82861.07 | AJ33: 60.42M | AK33: -0.0001 | AM33: 18-01-2026 | AN33: 14.23 | AO33: 14.58 | AP33: 14.98 | AQ33: 13.8 | AR33: 442.16K | AS33: -0.0353 | AU33: 18-01-2026 | AV33: 43.95 | AW33: 44.2 | AX33: 46.49 | AY33: 42 | AZ33: 18.57K | BA33: -0.0057 | BC33: 18-01-2026 | BD33: 43.52 | BE33: 44.4 | BF33: 45 | BG33: 40.83 | BH33: 735.51K | BI33: 0.0152
B34: Jun 23 2025 | C34: 56.14 | D34: 5614 | E34: - | F34: 5614 | G34: Jun 23 2025 | H34: 8405890 | I34: 153900 | J34: 8405890 | M34: 45831 | N34: 56.14 | O34: - | P34: 56.14 | Q34: 56.14 | R34: 56.14 | S34: 56.14 | V34: 28-09-2025 | W34: 69.62 | X34: 64.15 | Y34: 70.45 | Z34: 64.15 | AA34: 6.09K | AB34: 0.0051 | AE34: 46113 | AF34: 83576.24 | AG34: 85640.05 | AH34: 85883.5 | AI34: 83402.28 | AJ34: 93.88M | AK34: -0.0255 | AM34: 46327 | AN34: 14.75 | AO34: 15 | AP34: 15.4 | AQ34: 14.6 | AR34: 284.39K | AS34: -0.018 | AU34: 46327 | AV34: 44.2 | AW34: 40.1 | AX34: 44.21 | AY34: 40 | AZ34: 20.68K | BA34: 0.105 | BC34: 46327 | BD34: 42.87 | BE34: 44.25 | BF34: 49.49 | BG34: 42.85 | BH34: 1.97M | BI34: -0.0277
B35: Jun 16 2025 | C35: 56.14 | D35: 5614 | E35: - | F35: 5614 | G35: Jun 16 2025 | H35: 8240817 | I35: 63400 | J35: 8240817 | M35: 45824 | N35: 56.14 | O35: - | P35: 56.14 | Q35: 56.14 | R35: 56.14 | S35: 56.14 | V35: 21-09-2025 | W35: 69.27 | X35: 70.5 | Y35: 73.44 | Z35: 66 | AA35: 19.24K | AB35: -0.0114 | AE35: 28-12-2025 | AF35: 85762.01 | AG35: 85004.75 | AH35: 85812.27 | AI35: 84470.94 | AJ35: 110.34M | AK35: 0.0085 | AM35: 46113 | AN35: 15.02 | AO35: 14.15 | AP35: 16.39 | AQ35: 14.15 | AR35: 2.40M | AS35: 0.0351 | AU35: 46113 | AV35: 40 | AW35: 41 | AX35: 43.59 | AY35: 39.01 | AZ35: 17.85K | BA35: -0.0419 | BC35: 46113 | BD35: 44.09 | BE35: 37.03 | BF35: 44.75 | BG35: 36.8 | BH35: 1.75M | BI35: 0.1881
B36: Jun 9 2025 | C36: 56.14 | D36: 5614 | E36: 100 | F36: 5614 | G36: Jun 9 2025 | H36: 8111860 | I36: 50500 | J36: 8111860 | M36: 45817 | N36: 56.14 | O36: 100 | P36: 56.14 | Q36: 56.14 | R36: 56.14 | S36: 56.14 | V36: 14-09-2025 | W36: 70.07 | X36: 72 | Y36: 76 | Z36: 66.5 | AA36: 16.79K | AB36: -0.0253 | AE36: 21-12-2025 | AF36: 85041.45 | AG36: 85145.9 | AH36: 85738.18 | AI36: 84937.82 | AJ36: 25.47M | AK36: 0.0013 | AM36: 28-12-2025 | AN36: 14.51 | AO36: 15 | AP36: 15.6 | AQ36: 13.98 | AR36: 1.28M | AS36: -0.0365 | AU36: 28-12-2025 | AV36: 41.75 | AW36: 40.5 | AX36: 42.5 | AY36: 39.1 | AZ36: 14.86K | BA36: 0.0427 | BC36: 28-12-2025 | BD36: 37.11 | BE36: 36.6 | BF36: 37.74 | BG36: 34.01 | BH36: 927.76K | BI36: 0.0139
B37: Jun 2 2025 | C37: 53.47 | D37: 5347 | E37: - | F37: 5347 | G37: Jun 2 2025 | H37: 8218899 | I37: 71600 | J37: 8218899 | M37: 45810 | N37: 53.47 | O37: - | P37: 53.47 | Q37: 53.47 | R37: 53.47 | S37: 53.47 | V37: 45847 | W37: 71.89 | X37: 63.25 | Y37: 72.4 | Z37: 63.25 | AA37: 11.48K | AB37: -0.0024 | AE37: 14-12-2025 | AF37: 84929.36 | AG37: 84891.75 | AH37: 85278.63 | AI37: 84238.43 | AJ37: 55.51M | AK37: -0.004 | AM37: 21-12-2025 | AN37: 15.06 | AO37: 15.31 | AP37: 15.75 | AQ37: 14.91 | AR37: 514.36K | AS37: -0.017 | AU37: 21-12-2025 | AV37: 40.04 | AW37: 46.7 | AX37: 46.7 | AY37: 40.02 | AZ37: 12.67K | BA37: -0.1 | BC37: 21-12-2025 | BD37: 36.6 | BE37: 32.28 | BF37: 38.97 | BG37: 32 | BH37: 1.50M | BI37: 0.137
B38: May 26 2025 | C38: 53.47 | D38: 5347 | E38: - | F38: 5347 | G38: May 26 2025 | H38: 8145101 | I38: 74400 | J38: 8145101 | M38: 45803 | N38: 53.47 | O38: - | P38: 53.47 | Q38: 53.47 | R38: 53.47 | S38: 53.47 | V38: 31-08-2025 | W38: 72.06 | X38: 68.36 | Y38: 75 | Z38: 63 | AA38: 29.92K | AB38: 0.0277 | AE38: 45850 | AF38: 85267.66 | AG38: 85624.84 | AH38: 85722.97 | AI38: 84150.19 | AJ38: 51.94M | AK38: -0.0052 | AM38: 14-12-2025 | AN38: 15.32 | AO38: 13.85 | AP38: 16.65 | AQ38: 13.85 | AR38: 1.82M | AS38: 0.0888 | AU38: 14-12-2025 | AV38: 44.49 | AW38: 45.03 | AX38: 45.03 | AY38: 42.75 | AZ38: 20.03K | BA38: -0.0116 | BC38: 14-12-2025 | BD38: 32.19 | BE38: 28.57 | BF38: 32.31 | BG38: 27.65 | BH38: 1.33M | BI38: 0.1323
B39: May 19 2025 | C39: 53.47 | D39: 5347 | E39: - | F39: 5347 | G39: May 19 2025 | H39: 8172108 | I39: 47100 | J39: 8172108 | M39: 45796 | N39: 53.47 | O39: - | P39: 53.47 | Q39: 53.47 | R39: 53.47 | S39: 53.47 | V39: 24-08-2025 | W39: 70.12 | X39: 73.59 | Y39: 73.59 | Z39: 64.25 | AA39: 26.69K | AB39: -0.0472 | AE39: 30-11-2025 | AF39: 85712.37 | AG39: 86065.92 | AH39: 86159.02 | AI39: 84763.64 | AJ39: 57.49M | AK39: 0.0001 | AM39: 45850 | AN39: 14.07 | AO39: 14.36 | AP39: 14.56 | AQ39: 13.75 | AR39: 357.21K | AS39: -0.0303 | AU39: 45850 | AV39: 45.01 | AW39: 45.05 | AX39: 46.59 | AY39: 44.99 | AZ39: 8.83K | BA39: -0.0421 | BC39: 45850 | BD39: 28.43 | BE39: 30 | BF39: 30 | BG39: 27.2 | BH39: 1.33M | BI39: -0.0183
B40: May 12 2025 | C40: 53.47 | D40: 5347 | E40: 290 | F40: 5347 | G40: May 12 2025 | H40: 8233059 | I40: 70000 | J40: 8233059 | M40: 45789 | N40: 53.47 | O40: 53.47 | P40: 53.47 | Q40: 53.47 | R40: 53.47 | S40: 290 | V40: 17-08-2025 | W40: 73.59 | X40: 58.68 | Y40: 75.99 | Z40: 57.7 | AA40: 122.67K | AB40: 0.338 | AE40: 23-11-2025 | AF40: 85706.67 | AG40: 85320.04 | AH40: 86055.86 | AI40: 84478.13 | AJ40: 51.86M | AK40: 0.0056 | AM40: 30-11-2025 | AN40: 14.51 | AO40: 14.35 | AP40: 15.01 | AQ40: 14.02 | AR40: 2.19M | AS40: 0 | AU40: 30-11-2025 | AV40: 46.99 | AW40: 48 | AX40: 48 | AY40: 44.51 | AZ40: 13.83K | BA40: 0.0019 | BC40: 30-11-2025 | BD40: 28.96 | BE40: 27.5 | BF40: 30 | BG40: 26.93 | BH40: 1.61M | BI40: 0.0523
B41: May 5 2025 | C41: 53.47 | D41: 5347 | E41: - | F41: 5347 | G41: May 5 2025 | H41: 7945447 | I41: 49500 | J41: 7945447 | M41: 45782 | N41: 53.47 | O41: 53.47 | P41: 53.47 | Q41: 53.47 | R41: 53.47 | S41: - | V41: 45938 | W41: 55 | X41: 52.7 | Y41: 56.9 | Z41: 51.26 | AA41: 24.47K | AB41: 0.0427 | AE41: 16-11-2025 | AF41: 85231.92 | AG41: 84700.5 | AH41: 85801.7 | AI41: 84525.98 | AJ41: 68.47M | AK41: 0.0079 | AM41: 23-11-2025 | AN41: 14.51 | AO41: 13.45 | AP41: 15.35 | AQ41: 13.45 | AR41: 6.65M | AS41: 0.0951 | AU41: 23-11-2025 | AV41: 46.9 | AW41: 48 | AX41: 48 | AY41: 44.5 | AZ41: 11.20K | BA41: 0.0017 | BC41: 23-11-2025 | BD41: 27.52 | BE41: 26.59 | BF41: 27.53 | BG41: 25.81 | BH41: 471.22K | BI41: 0.0508
...

Sheet Guru BETA
B8: Regression Beta - 2 Years Monthly
B10: Guru Krupa Gems and Jewellery Ltd | F10: SENSEX Bse Return
B12: Date | C12: Close Price | D12: Return | F12: Date | G12: Close Price | H12: Return | J12: Beta Drafting | N12: SUMMARY OUTPUT
B13: 25-01-2026 | C13: 41.46 | F13: 25-01-2026 | G13: 82269.78
B14: 18-01-2026 | C14: 43.52 | D14: =C14/C13-1 -> 0.049686445 | F14: 18-01-2026 | G14: 81537.7 | H14: =G14/G13-1 -> -0.0088985287 | N14: Regression Statistics
B15: 46327 | C15: 42.87 | D15: =C15/C14-1 -> -0.014935662 | F15: 46327 | G15: 83570.35 | H15: =G15/G14-1 -> 0.024928959 | J15: Levered Raw Beta | K15: =O29 -> -0.033964804 | N15: Multiple R | O15: 0.0075600209
B16: 46113 | C16: 44.09 | D16: =C16/C15-1 -> 0.028458129 | F16: 46113 | G16: 83576.24 | H16: =G16/G15-1 -> 7.0479542e-05 | J16: Raw Beta Weight | K16: 0.75 | N16: R Square | O16: 5.7153917e-05
B17: 28-12-2025 | C17: 37.11 | D17: =C17/C16-1 -> -0.15831254 | F17: 28-12-2025 | G17: 85762.01 | H17: =G17/G16-1 -> 0.026153007 | N17: Adjusted R Square | O17: -0.0094661113
B18: 21-12-2025 | C18: 36.6 | D18: =C18/C17-1 -> -0.013742926 | F18: 21-12-2025 | G18: 85041.45 | H18: =G18/G17-1 -> -0.0084018553 | J18: Market Beta | K18: 1 | N18: Standard Error | O18: 0.074901478
B19: 14-12-2025 | C19: 32.19 | D19: =C19/C18-1 -> -0.1204918 | F19: 14-12-2025 | G19: 84929.36 | H19: =G19/G18-1 -> -0.0013180631 | J19: Market Beta Weight | K19: 0.25 | N19: Observations | O19: 107
B20: 45850 | C20: 28.43 | D20: =C20/C19-1 -> -0.11680646 | F20: 45850 | G20: 85267.66 | H20: =G20/G19-1 -> 0.0039833104
B21: 30-11-2025 | C21: 28.96 | D21: =C21/C20-1 -> 0.018642279 | F21: 30-11-2025 | G21: 85712.37 | H21: =G21/G20-1 -> 0.0052154592 | J21: Adjusted Beta | K21: =(K15*K16)+(K18*K19) -> 0.2245264 | N21: ANOVA
B22: 23-11-2025 | C22: 27.52 | D22: =C22/C21-1 -> -0.049723757 | F22: 23-11-2025 | G22: 85706.67 | H22: =G22/G21-1 -> -6.6501486e-05 | O22: df | P22: SS | Q22: MS | R22: F | S22: Significance F
B23: 16-11-2025 | C23: 26.19 | D23: =C23/C22-1 -> -0.048328488 | F23: 16-11-2025 | G23: 85231.92 | H23: =G23/G22-1 -> -0.0055392422 | N23: Regression | O23: 1 | P23: 3.3669828e-05 | Q23: 3.3669828e-05 | R23: 0.0060015043 | S23: 0.93839758
B24: 45911 | C24: 25.45 | D24: =C24/C23-1 -> -0.028255059 | F24: 45911 | G24: 84562.78 | H24: =G24/G23-1 -> -0.0078508146 | N24: Residual | O24: 105 | P24: 0.5890743 | Q24: 0.0056102314
B25: 45699 | C25: 24.92 | D25: =C25/C24-1 -> -0.020825147 | F25: 45699 | G25: 83216.28 | H25: =G25/G24-1 -> -0.015923081 | N25: Total | O25: 106 | P25: 0.58910797
B26: 26-10-2025 | C26: 23.97 | D26: =C26/C25-1 -> -0.03812199 | F26: 26-10-2025 | G26: 83938.71 | H26: =G26/G25-1 -> 0.0086813542
B27: 19-10-2025 | C27: 23.47 | D27: =C27/C26-1 -> -0.020859408 | F27: 19-10-2025 | G27: 84211.88 | H27: =G27/G26-1 -> 0.0032543984 | O27: Coefficients | P27: Standard Error | Q27: t Stat | R27: P-value | S27: Lower 95% | T27: Upper 95% | U27: Lower 95.0% | V27: Upper 95.0%
B28: 46001 | C28: 21.74 | D28: =C28/C27-1 -> -0.073711121 | F28: 46001 | G28: 83952.19 | H28: =G28/G27-1 -> -0.0030837692 | N28: Intercept | O28: -0.0039774271 | P28: 0.0072572163 | Q28: -0.54806512 | R28: 0.58481049 | S28: -0.018367146 | T28: 0.010412292 | U28: -0.018367146 | V28: 0.010412292
B29: 45787 | C29: 20.27 | D29: =C29/C28-1 -> -0.067617295 | F29: 45787 | G29: 82500.82 | H29: =G29/G28-1 -> -0.017288054 | N29: X Variable 1 | O29: -0.033964804 | P29: 0.43842878 | Q29: -0.077469376 | R29: 0.93839758 | S29: -0.90328808 | T29: 0.83535847 | U29: -0.90328808 | V29: 0.83535847
B30: 28-09-2025 | C30: 20.86 | D30: =C30/C29-1 -> 0.029107055 | F30: 28-09-2025 | G30: 81207.17 | H30: =G30/G29-1 -> -0.01568045
B31: 21-09-2025 | C31: 19.56 | D31: =C31/C30-1 -> -0.06232023 | F31: 21-09-2025 | G31: 80426.46 | H31: =G31/G30-1 -> -0.0096138063
B32: 14-09-2025 | C32: 21.12 | D32: =C32/C31-1 -> 0.079754601 | F32: 14-09-2025 | G32: 82626.23 | H32: =G32/G31-1 -> 0.027351322
B33: 45847 | C33: 21.14 | D33: =C33/C32-1 -> 0.0009469697 | F33: 45847 | G33: 81904.7 | H33: =G33/G32-1 -> -0.008732457
B34: 31-08-2025 | C34: 20.69 | D34: =C34/C33-1 -> -0.02128666 | F34: 31-08-2025 | G34: 80710.76 | H34: =G34/G33-1 -> -0.014577185
B35: 24-08-2025 | C35: 21.13 | D35: =C35/C34-1 -> 0.021266312 | F35: 24-08-2025 | G35: 79809.65 | H35: =G35/G34-1 -> -0.011164682
B36: 17-08-2025 | C36: 21.12 | D36: =C36/C35-1 -> -0.00047326077 | F36: 17-08-2025 | G36: 81306.85 | H36: =G36/G35-1 -> 0.018759636
B37: 45938 | C37: 20.16 | D37: =C37/C36-1 -> -0.045454545 | F37: 45938 | G37: 80597.66 | H37: =G37/G36-1 -> -0.0087223893
B38: 45724 | C38: 19.99 | D38: =C38/C37-1 -> -0.0084325397 | F38: 45724 | G38: 79857.79 | H38: =G38/G37-1 -> -0.009179795
B39: 27-07-2025 | C39: 20.21 | D39: =C39/C38-1 -> 0.011005503 | F39: 27-07-2025 | G39: 80599.91 | H39: =G39/G38-1 -> 0.0092930195
B40: 20-07-2025 | C40: 17.7 | D40: =C40/C39-1 -> -0.12419594 | F40: 20-07-2025 | G40: 81463.09 | H40: =G40/G39-1 -> 0.010709441
B41: 13-07-2025 | C41: 18.43 | D41: =C41/C40-1 -> 0.041242938 | F41: 13-07-2025 | G41: 81757.73 | H41: =G41/G40-1 -> 0.0036168527
B42: 45815 | C42: 16.97 | D42: =C42/C41-1 -> -0.079218665 | F42: 45815 | G42: 82500.47 | H42: =G42/G41-1 -> 0.0090846456
B43: 29-06-2025 | C43: 16.22 | D43: =C43/C42-1 -> -0.044195639 | F43: 29-06-2025 | G43: 83432.89 | H43: =G43/G42-1 -> 0.011301996
B44: 22-06-2025 | C44: 12.3 | D44: =C44/C43-1 -> -0.24167694 | F44: 22-06-2025 | G44: 84058.9 | H44: =G44/G43-1 -> 0.0075031561
B45: 15-06-2025 | C45: 12.29 | D45: =C45/C44-1 -> -0.00081300813 | F45: 15-06-2025 | G45: 82408.17 | H45: =G45/G44-1 -> -0.019637778
B46: 45875 | C46: 11.9 | D46: =C46/C45-1 -> -0.031733116 | F46: 45875 | G46: 81118.6 | H46: =G46/G45-1 -> -0.01564857
B47: 45663 | C47: 11.71 | D47: =C47/C46-1 -> -0.015966387 | F47: 45663 | G47: 82188.99 | H47: =G47/G46-1 -> 0.013195371
B48: 25-05-2025 | C48: 11.68 | D48: =C48/C47-1 -> -0.0025619129 | F48: 25-05-2025 | G48: 81451.01 | H48: =G48/G47-1 -> -0.0089790616
B49: 18-05-2025 | C49: 12.16 | D49: =C49/C48-1 -> 0.04109589 | F49: 18-05-2025 | G49: 81721.08 | H49: =G49/G48-1 -> 0.0033157354
...

Sheet Mishka Exim Ltd
A8: Regression Beta - 2 Years Monthly
A10: Mishka Exim Ltd | E10: SENSEX Bse Return
M11: SUMMARY OUTPUT
A12: Date | B12: Close Price | C12: Return | E12: Date | F12: Close Price | G12: Return | I12: Beta Drafting
A13: 25-01-2026 | B13: 40.7 | E13: 25-01-2026 | F13: 82269.78 | M13: Regression Statistics
A14: 18-01-2026 | B14: 43.95 | C14: =B14/B13-1 -> 0.07985258 | E14: 18-01-2026 | F14: 81537.7 | G14: =F14/F13-1 -> -0.0088985287 | M14: Multiple R | N14: 0.15973607
A15: 46327 | B15: 44.2 | C15: =B15/B14-1 -> 0.0056882821 | E15: 46327 | F15: 83570.35 | G15: =F15/F14-1 -> 0.024928959 | I15: Levered Raw Beta | J15: =N28 -> 0.69271189 | M15: R Square | N15: 0.025515613
A16: 46113 | B16: 40 | C16: =B16/B15-1 -> -0.095022624 | E16: 46113 | F16: 83576.24 | G16: =F16/F15-1 -> 7.0479542e-05 | I16: Raw Beta Weight | J16: 0.75 | M16: Adjusted R Square | N16: 0.016234809
A17: 28-12-2025 | B17: 41.75 | C17: =B17/B16-1 -> 0.04375 | E17: 28-12-2025 | F17: 85762.01 | G17: =F17/F16-1 -> 0.026153007 | M17: Standard Error | N17: 0.071372971
A18: 21-12-2025 | B18: 40.04 | C18: =B18/B17-1 -> -0.040958084 | E18: 21-12-2025 | F18: 85041.45 | G18: =F18/F17-1 -> -0.0084018553 | I18: Market Beta | J18: 1 | M18: Observations | N18: 107
A19: 14-12-2025 | B19: 44.49 | C19: =B19/B18-1 -> 0.11113886 | E19: 14-12-2025 | F19: 84929.36 | G19: =F19/F18-1 -> -0.0013180631 | I19: Market Beta Weight | J19: 0.25
A20: 45850 | B20: 45.01 | C20: =B20/B19-1 -> 0.01168802 | E20: 45850 | F20: 85267.66 | G20: =F20/F19-1 -> 0.0039833104 | M20: ANOVA
A21: 30-11-2025 | B21: 46.99 | C21: =B21/B20-1 -> 0.043990224 | E21: 30-11-2025 | F21: 85712.37 | G21: =F21/F20-1 -> 0.0052154592 | I21: Adjusted Beta | J21: =(J15*J16)+(J18*J19) -> 0.76953392 | N21: df | O21: SS | P21: MS | Q21: F | R21: Significance F
A22: 23-11-2025 | B22: 46.9 | C22: =B22/B21-1 -> -0.0019153011 | E22: 23-11-2025 | F22: 85706.67 | G22: =F22/F21-1 -> -6.6501486e-05 | M22: Regression | N22: 1 | O22: 0.014005156 | P22: 0.014005156 | Q22: 2.7492891 | R22: 0.10028235
A23: 16-11-2025 | B23: 46.82 | C23: =B23/B22-1 -> -0.0017057569 | E23: 16-11-2025 | F23: 85231.92 | G23: =F23/F22-1 -> -0.0055392422 | M23: Residual | N23: 105 | O23: 0.5348806 | P23: 0.005094101
A24: 45911 | B24: 44.88 | C24: =B24/B23-1 -> -0.041435284 | E24: 45911 | F24: 84562.78 | G24: =F24/F23-1 -> -0.0078508146 | M24: Total | N24: 106 | O24: 0.54888576
A25: 45699 | B25: 46.86 | C25: =B25/B24-1 -> 0.044117647 | E25: 45699 | F25: 83216.28 | G25: =F25/F24-1 -> -0.015923081
A26: 26-10-2025 | B26: 38.56 | C26: =B26/B25-1 -> -0.17712335 | E26: 26-10-2025 | F26: 83938.71 | G26: =F26/F25-1 -> 0.0086813542 | N26: Coefficients | O26: Standard Error | P26: t Stat | Q26: P-value | R26: Lower 95% | S26: Upper 95% | T26: Lower 95.0% | U26: Upper 95.0%
A27: 19-10-2025 | B27: 37.09 | C27: =B27/B26-1 -> -0.038122407 | E27: 19-10-2025 | F27: 84211.88 | G27: =F27/F26-1 -> 0.0032543984 | M27: Intercept | N27: 0.002053945 | O27: 0.0069153387 | P27: 0.29701294 | Q27: 0.7670434 | R27: -0.011657894 | S27: 0.015765784 | T27: -0.011657894 | U27: 0.015765784
A28: 46001 | B28: 36.64 | C28: =B28/B27-1 -> -0.01213265 | E28: 46001 | F28: 83952.19 | G28: =F28/F27-1 -> -0.0030837692 | M28: X Variable 1 | N28: 0.69271189 | O28: 0.41777499 | P28: 1.658098 | Q28: 0.10028235 | R28: -0.13565874 | S28: 1.5210825 | T28: -0.13565874 | U28: 1.5210825
A29: 45787 | B29: 36 | C29: =B29/B28-1 -> -0.017467249 | E29: 45787 | F29: 82500.82 | G29: =F29/F28-1 -> -0.017288054
A30: 28-09-2025 | B30: 35 | C30: =B30/B29-1 -> -0.027777778 | E30: 28-09-2025 | F30: 81207.17 | G30: =F30/F29-1 -> -0.01568045
A31: 21-09-2025 | B31: 36.23 | C31: =B31/B30-1 -> 0.035142857 | E31: 21-09-2025 | F31: 80426.46 | G31: =F31/F30-1 -> -0.0096138063
A32: 14-09-2025 | B32: 38 | C32: =B32/B31-1 -> 0.04885454 | E32: 14-09-2025 | F32: 82626.23 | G32: =F32/F31-1 -> 0.027351322
A33: 45847 | B33: 38.08 | C33: =B33/B32-1 -> 0.0021052632 | E33: 45847 | F33: 81904.7 | G33: =F33/F32-1 -> -0.008732457
A34: 31-08-2025 | B34: 36.5 | C34: =B34/B33-1 -> -0.041491597 | E34: 31-08-2025 | F34: 80710.76 | G34: =F34/F33-1 -> -0.014577185
A35: 24-08-2025 | B35: 35.86 | C35: =B35/B34-1 -> -0.017534247 | E35: 24-08-2025 | F35: 79809.65 | G35: =F35/F34-1 -> -0.011164682
A36: 17-08-2025 | B36: 35.66 | C36: =B36/B35-1 -> -0.0055772448 | E36: 17-08-2025 | F36: 81306.85 | G36: =F36/F35-1 -> 0.018759636
A37: 45938 | B37: 35.21 | C37: =B37/B36-1 -> -0.012619181 | E37: 45938 | F37: 80597.66 | G37: =F37/F36-1 -> -0.0087223893
A38: 45724 | B38: 33.62 | C38: =B38/B37-1 -> -0.045157626 | E38: 45724 | F38: 79857.79 | G38: =F38/F37-1 -> -0.009179795
A39: 27-07-2025 | B39: 37.99 | C39: =B39/B38-1 -> 0.12998215 | E39: 27-07-2025 | F39: 80599.91 | G39: =F39/F38-1 -> 0.0092930195
A40: 20-07-2025 | B40: 44.56 | C40: =B40/B39-1 -> 0.17294025 | E40: 20-07-2025 | F40: 81463.09 | G40: =F40/F39-1 -> 0.010709441
A41: 13-07-2025 | B41: 39.09 | C41: =B41/B40-1 -> -0.12275583 | E41: 13-07-2025 | F41: 81757.73 | G41: =F41/F40-1 -> 0.0036168527
A42: 45815 | B42: 28.39 | C42: =B42/B41-1 -> -0.2737273 | E42: 45815 | F42: 82500.47 | G42: =F42/F41-1 -> 0.0090846456
A43: 29-06-2025 | B43: 26.37 | C43: =B43/B42-1 -> -0.071151814 | E43: 29-06-2025 | F43: 83432.89 | G43: =F43/F42-1 -> 0.011301996
A44: 22-06-2025 | B44: 27.98 | C44: =B44/B43-1 -> 0.061054228 | E44: 22-06-2025 | F44: 84058.9 | G44: =F44/F43-1 -> 0.0075031561
A45: 15-06-2025 | B45: 27.03 | C45: =B45/B44-1 -> -0.033952823 | E45: 15-06-2025 | F45: 82408.17 | G45: =F45/F44-1 -> -0.019637778
A46: 45875 | B46: 28.43 | C46: =B46/B45-1 -> 0.051794303 | E46: 45875 | F46: 81118.6 | G46: =F46/F45-1 -> -0.01564857
A47: 45663 | B47: 26 | C47: =B47/B46-1 -> -0.085473092 | E47: 45663 | F47: 82188.99 | G47: =F47/F46-1 -> 0.013195371
A48: 25-05-2025 | B48: 25.09 | C48: =B48/B47-1 -> -0.035 | E48: 25-05-2025 | F48: 81451.01 | G48: =F48/F47-1 -> -0.0089790616
...

Sheet Moksh BETA
A8: Regression Beta - 2 Years Monthly
A10: Moksh Ornaments Ltd | E10: SENSEX Bse Return
A12: Date | B12: Close Price | C12: Return | E12: Date | F12: Close Price | G12: Return | I12: Beta Drafting
A13: 25-01-2026 | B13: 13.75 | E13: 25-01-2026 | F13: 82269.78 | O13: SUMMARY OUTPUT
A14: 18-01-2026 | B14: 14.23 | C14: =B14/B13-1 -> 0.034909091 | E14: 18-01-2026 | F14: 81537.7 | G14: =F14/F13-1 -> -0.0088985287
A15: 46327 | B15: 14.75 | C15: =B15/B14-1 -> 0.036542516 | E15: 46327 | F15: 83570.35 | G15: =F15/F14-1 -> 0.024928959 | I15: Levered Raw Beta | J15: =P30 -> 0.58487445 | O15: Regression Statistics
A16: 46113 | B16: 15.02 | C16: =B16/B15-1 -> 0.018305085 | E16: 46113 | F16: 83576.24 | G16: =F16/F15-1 -> 7.0479542e-05 | I16: Raw Beta Weight | J16: 0.75 | O16: Multiple R | P16: 0.13665178
A17: 28-12-2025 | B17: 14.51 | C17: =B17/B16-1 -> -0.033954727 | E17: 28-12-2025 | F17: 85762.01 | G17: =F17/F16-1 -> 0.026153007 | O17: R Square | P17: 0.018673709
A18: 21-12-2025 | B18: 15.06 | C18: =B18/B17-1 -> 0.037904893 | E18: 21-12-2025 | F18: 85041.45 | G18: =F18/F17-1 -> -0.0084018553 | I18: Market Beta | J18: 1 | O18: Adjusted R Square | P18: 0.0093277444
A19: 14-12-2025 | B19: 15.32 | C19: =B19/B18-1 -> 0.017264276 | E19: 14-12-2025 | F19: 84929.36 | G19: =F19/F18-1 -> -0.0013180631 | I19: Market Beta Weight | J19: 0.25 | O19: Standard Error | P19: 0.070688824
A20: 45850 | B20: 14.07 | C20: =B20/B19-1 -> -0.081592689 | E20: 45850 | F20: 85267.66 | G20: =F20/F19-1 -> 0.0039833104 | O20: Observations | P20: 107
A21: 30-11-2025 | B21: 14.51 | C21: =B21/B20-1 -> 0.03127221 | E21: 30-11-2025 | F21: 85712.37 | G21: =F21/F20-1 -> 0.0052154592 | I21: Adjusted Beta | J21: =(J15*J16)+(J18*J19) -> 0.68865584
A22: 23-11-2025 | B22: 14.51 | C22: =B22/B21-1 -> 0 | E22: 23-11-2025 | F22: 85706.67 | G22: =F22/F21-1 -> -6.6501486e-05 | O22: ANOVA
A23: 16-11-2025 | B23: 13.25 | C23: =B23/B22-1 -> -0.086836664 | E23: 16-11-2025 | F23: 85231.92 | G23: =F23/F22-1 -> -0.0055392422 | P23: df | Q23: SS | R23: MS | S23: F | T23: Significance F
A24: 45911 | B24: 15.17 | C24: =B24/B23-1 -> 0.14490566 | E24: 45911 | F24: 84562.78 | G24: =F24/F23-1 -> -0.0078508146 | O24: Regression | P24: 1 | Q24: 0.0099840782 | R24: 0.0099840782 | S24: 1.9980505 | T24: 0.16045954
A25: 45699 | B25: 14.28 | C25: =B25/B24-1 -> -0.058668425 | E25: 45699 | F25: 83216.28 | G25: =F25/F24-1 -> -0.015923081 | O25: Residual | P25: 105 | Q25: 0.52467554 | R25: 0.0049969099
A26: 26-10-2025 | B26: 13.9 | C26: =B26/B25-1 -> -0.026610644 | E26: 26-10-2025 | F26: 83938.71 | G26: =F26/F25-1 -> 0.0086813542 | O26: Total | P26: 106 | Q26: 0.53465962
A27: 19-10-2025 | B27: 14.25 | C27: =B27/B26-1 -> 0.025179856 | E27: 19-10-2025 | F27: 84211.88 | G27: =F27/F26-1 -> 0.0032543984
A28: 46001 | B28: 14.3 | C28: =B28/B27-1 -> 0.0035087719 | E28: 46001 | F28: 83952.19 | G28: =F28/F27-1 -> -0.0030837692 | P28: Coefficients | Q28: Standard Error | R28: t Stat | S28: P-value | T28: Lower 95% | U28: Upper 95% | V28: Lower 95.0% | W28: Upper 95.0%
A29: 45787 | B29: 15.14 | C29: =B29/B28-1 -> 0.058741259 | E29: 45787 | F29: 82500.82 | G29: =F29/F28-1 -> -0.017288054 | O29: Intercept | P29: 0.002570253 | Q29: 0.0068490516 | R29: 0.37527137 | S29: 0.70821565 | T29: -0.011010151 | U29: 0.016150657 | V29: -0.011010151 | W29: 0.016150657
A30: 28-09-2025 | B30: 14.97 | C30: =B30/B29-1 -> -0.011228534 | E30: 28-09-2025 | F30: 81207.17 | G30: =F30/F29-1 -> -0.01568045 | O30: X Variable 1 | P30: 0.58487445 | Q30: 0.4137704 | R30: 1.4135241 | S30: 0.16045954 | T30: -0.23555583 | U30: 1.4053047 | V30: -0.23555583 | W30: 1.4053047
A31: 21-09-2025 | B31: 14.1 | C31: =B31/B30-1 -> -0.058116232 | E31: 21-09-2025 | F31: 80426.46 | G31: =F31/F30-1 -> -0.0096138063
A32: 14-09-2025 | B32: 14.8 | C32: =B32/B31-1 -> 0.04964539 | E32: 14-09-2025 | F32: 82626.23 | G32: =F32/F31-1 -> 0.027351322
A33: 45847 | B33: 13.89 | C33: =B33/B32-1 -> -0.061486486 | E33: 45847 | F33: 81904.7 | G33: =F33/F32-1 -> -0.008732457
A34: 31-08-2025 | B34: 13.9 | C34: =B34/B33-1 -> 0.0007199424 | E34: 31-08-2025 | F34: 80710.76 | G34: =F34/F33-1 -> -0.014577185
A35: 24-08-2025 | B35: 13.58 | C35: =B35/B34-1 -> -0.023021583 | E35: 24-08-2025 | F35: 79809.65 | G35: =F35/F34-1 -> -0.011164682
A36: 17-08-2025 | B36: 13.81 | C36: =B36/B35-1 -> 0.016936672 | E36: 17-08-2025 | F36: 81306.85 | G36: =F36/F35-1 -> 0.018759636
A37: 45938 | B37: 13.67 | C37: =B37/B36-1 -> -0.010137581 | E37: 45938 | F37: 80597.66 | G37: =F37/F36-1 -> -0.0087223893
A38: 45724 | B38: 13.74 | C38: =B38/B37-1 -> 0.0051207023 | E38: 45724 | F38: 79857.79 | G38: =F38/F37-1 -> -0.009179795
A39: 27-07-2025 | B39: 13.83 | C39: =B39/B38-1 -> 0.0065502183 | E39: 27-07-2025 | F39: 80599.91 | G39: =F39/F38-1 -> 0.0092930195
A40: 20-07-2025 | B40: 13.82 | C40: =B40/B39-1 -> -0.0007230658 | E40: 20-07-2025 | F40: 81463.09 | G40: =F40/F39-1 -> 0.010709441
A41: 13-07-2025 | B41: 14.57 | C41: =B41/B40-1 -> 0.054269175 | E41: 13-07-2025 | F41: 81757.73 | G41: =F41/F40-1 -> 0.0036168527
A42: 45815 | B42: 14.64 | C42: =B42/B41-1 -> 0.0048043926 | E42: 45815 | F42: 82500.47 | G42: =F42/F41-1 -> 0.0090846456
A43: 29-06-2025 | B43: 14.84 | C43: =B43/B42-1 -> 0.013661202 | E43: 29-06-2025 | F43: 83432.89 | G43: =F43/F42-1 -> 0.011301996
A44: 22-06-2025 | B44: 14.4 | C44: =B44/B43-1 -> -0.029649596 | E44: 22-06-2025 | F44: 84058.9 | G44: =F44/F43-1 -> 0.0075031561
A45: 15-06-2025 | B45: 14.71 | C45: =B45/B44-1 -> 0.021527778 | E45: 15-06-2025 | F45: 82408.17 | G45: =F45/F44-1 -> -0.019637778
A46: 45875 | B46: 14.84 | C46: =B46/B45-1 -> 0.0088375255 | E46: 45875 | F46: 81118.6 | G46: =F46/F45-1 -> -0.01564857
A47: 45663 | B47: 14.85 | C47: =B47/B46-1 -> 0.00067385445 | E47: 45663 | F47: 82188.99 | G47: =F47/F46-1 -> 0.013195371
A48: 25-05-2025 | B48: 15.11 | C48: =B48/B47-1 -> 0.017508418 | E48: 25-05-2025 | F48: 81451.01 | G48: =F48/F47-1 -> -0.0089790616
A49: 18-05-2025 | B49: 13.99 | C49: =B49/B48-1 -> -0.074123097 | E49: 18-05-2025 | F49: 81721.08 | G49: =F49/F48-1 -> 0.0033157354
...

Sheet beta sj corpoation
L3: 1
B6: Regression Beta - 2 Years Monthly
B8: SJ Corporation Ltd | F8: SENSEX Bse Return
R9: SUMMARY OUTPUT
B10: Date | C10: Close Price | D10: Return | F10: Date | G10: Close Price | H10: Return
B11: Jan 26 2026 | C11: 68.07 | F11: Jan 26 2026 | G11: 8226978 | K11: Beta Drafting | R11: Regression Statistics
B12: Jan 19 2026 | C12: 65 | D12: =C12/C11-1 -> -0.045100632 | F12: Jan 19 2026 | G12: 8153770 | H12: =G12/G11-1 -> -0.0088985287 | R12: Multiple R | S12: 0.1396718
B13: Jan 12 2026 | C13: 65 | D13: =C13/C12-1 -> 0 | F13: Jan 12 2026 | G13: 8357035 | H13: =G13/G12-1 -> 0.024928959 | R13: R Square | S13: 0.019508212
B14: Jan 5 2026 | C14: 65 | D14: =C14/C13-1 -> 0 | F14: Jan 5 2026 | G14: 8357624 | H14: =G14/G13-1 -> 7.0479542e-05 | K14: Levered Raw Beta | L14: =R29 -> -0.1905929 | R14: Adjusted R Square | S14: 0.01025829
B15: Dec 29 2025 | C15: 65 | D15: =C15/C14-1 -> 0 | F15: Dec 29 2025 | G15: 8576201 | H15: =G15/G14-1 -> 0.026153007 | K15: Raw Beta Weight | L15: 0.75 | R15: Standard Error | S15: 0.022355726
B16: Dec 22 2025 | C16: 65 | D16: =C16/C15-1 -> 0 | F16: Dec 22 2025 | G16: 8504145 | H16: =G16/G15-1 -> -0.0084018553 | R16: Observations | S16: 108
B17: Dec 15 2025 | C17: 65 | D17: =C17/C16-1 -> 0 | F17: Dec 15 2025 | G17: 8492936 | H17: =G17/G16-1 -> -0.0013180631 | K17: Market Beta | L17: 1
B18: Dec 8 2025 | C18: 65 | D18: =C18/C17-1 -> 0 | F18: Dec 8 2025 | G18: 8526766 | H18: =G18/G17-1 -> 0.0039833104 | K18: Market Beta Weight | L18: 0.25 | R18: ANOVA
B19: Dec 1 2025 | C19: 65 | D19: =C19/C18-1 -> 0 | F19: Dec 1 2025 | G19: 8571237 | H19: =G19/G18-1 -> 0.0052154592 | S19: df | T19: SS | U19: MS | V19: F | W19: Significance F
B20: Nov 24 2025 | C20: 65 | D20: =C20/C19-1 -> 0 | F20: Nov 24 2025 | G20: 8570667 | H20: =G20/G19-1 -> -6.6501486e-05 | K20: Adjusted Beta | L20: =(L14*L15)+(L17*L18) -> 0.10705532 | R20: Regression | S20: 1 | T20: 0.0010540396 | U20: 0.0010540396 | V20: 2.1090136 | W20: 0.14938731
B21: Nov 17 2025 | C21: 65 | D21: =C21/C20-1 -> 0 | F21: Nov 17 2025 | G21: 8523192 | H21: =G21/G20-1 -> -0.0055392422 | R21: Residual | S21: 106 | T21: 0.05297652 | U21: 0.00049977849
B22: Nov 10 2025 | C22: 65 | D22: =C22/C21-1 -> 0 | F22: Nov 10 2025 | G22: 8456278 | H22: =G22/G21-1 -> -0.0078508146 | R22: Total | S22: 107 | T22: 0.05403056
B23: Nov 3 2025 | C23: 65 | D23: =C23/C22-1 -> 0 | F23: Nov 3 2025 | G23: 8321628 | H23: =G23/G22-1 -> -0.015923081
B24: Oct 27 2025 | C24: 65 | D24: =C24/C23-1 -> 0 | F24: Oct 27 2025 | G24: 8393871 | H24: =G24/G23-1 -> 0.0086813542 | S24: Coefficients | T24: Standard Error | U24: t Stat | V24: P-value | W24: Lower 95% | X24: Upper 95% | Y24: Lower 95.0% | Z24: Upper 95.0%
B25: Oct 20 2025 | C25: 65 | D25: =C25/C24-1 -> 0 | F25: Oct 20 2025 | G25: 8421188 | H25: =G25/G24-1 -> 0.0032543984 | R25: Intercept | S25: -0.0049737563 | T25: 0.002155989 | U25: -2.3069488 | V25: 0.023001605 | W25: -0.0092482143 | X25: -0.00069929834 | Y25: -0.0092482143 | Z25: -0.00069929834
B26: Oct 13 2025 | C26: 64.97 | D26: =C26/C25-1 -> -0.00046153846 | F26: Oct 13 2025 | G26: 8395219 | H26: =G26/G25-1 -> -0.0030837692 | R26: X Variable 1 | S26: -0.1905929 | T26: 0.13124025 | U26: -1.4522443 | V26: 0.14938731 | W26: -0.45078946 | X26: 0.069603649 | Y26: -0.45078946 | Z26: 0.069603649
B27: Oct 6 2025 | C27: 64.97 | D27: =C27/C26-1 -> 0 | F27: Oct 6 2025 | G27: 8250082 | H27: =G27/G26-1 -> -0.017288054
B28: Sep 29 2025 | C28: 64.97 | D28: =C28/C27-1 -> 0 | F28: Sep 29 2025 | G28: 8120717 | H28: =G28/G27-1 -> -0.01568045
B29: Sep 22 2025 | C29: 64.97 | D29: =C29/C28-1 -> 0 | F29: Sep 22 2025 | G29: 8042646 | H29: =G29/G28-1 -> -0.0096138063 | R29: =S26 -> -0.1905929
B30: Sep 15 2025 | C30: 64.97 | D30: =C30/C29-1 -> 0 | F30: Sep 15 2025 | G30: 8262623 | H30: =G30/G29-1 -> 0.027351322
B31: Sep 8 2025 | C31: 64.97 | D31: =C31/C30-1 -> 0 | F31: Sep 8 2025 | G31: 8190470 | H31: =G31/G30-1 -> -0.008732457
B32: Sep 1 2025 | C32: 64.97 | D32: =C32/C31-1 -> 0 | F32: Sep 1 2025 | G32: 8071076 | H32: =G32/G31-1 -> -0.014577185
B33: Aug 25 2025 | C33: 64.97 | D33: =C33/C32-1 -> 0 | F33: Aug 25 2025 | G33: 7980965 | H33: =G33/G32-1 -> -0.011164682
B34: Aug 18 2025 | C34: 58.94 | D34: =C34/C33-1 -> -0.092812067 | F34: Aug 18 2025 | G34: 8130685 | H34: =G34/G33-1 -> 0.018759636
B35: Aug 11 2025 | C35: 58.94 | D35: =C35/C34-1 -> 0 | F35: Aug 11 2025 | G35: 8059766 | H35: =G35/G34-1 -> -0.0087223893
B36: Aug 4 2025 | C36: 58.94 | D36: =C36/C35-1 -> 0 | F36: Aug 4 2025 | G36: 7985779 | H36: =G36/G35-1 -> -0.009179795
B37: Jul 28 2025 | C37: 58.94 | D37: =C37/C36-1 -> 0 | F37: Jul 28 2025 | G37: 8059991 | H37: =G37/G36-1 -> 0.0092930195
B38: Jul 21 2025 | C38: 58.94 | D38: =C38/C37-1 -> 0 | F38: Jul 21 2025 | G38: 8146309 | H38: =G38/G37-1 -> 0.010709441
B39: Jul 14 2025 | C39: 58.94 | D39: =C39/C38-1 -> 0 | F39: Jul 14 2025 | G39: 8175773 | H39: =G39/G38-1 -> 0.0036168527
B40: Jul 7 2025 | C40: 56.14 | D40: =C40/C39-1 -> -0.047505938 | F40: Jul 7 2025 | G40: 8250047 | H40: =G40/G39-1 -> 0.0090846456
B41: Jun 30 2025 | C41: 56.14 | D41: =C41/C40-1 -> 0 | F41: Jun 30 2025 | G41: 8343289 | H41: =G41/G40-1 -> 0.011301996
... B119: Jan 1 2024 | C119: 39.51 | D119: =C119/C118-1 -> 0 | F119: Jan 1 2024 | G119: 7202615 | H119: =G119/G118-1 -> -0.0074729445

Sheet Narbada beta
A7: Regression Beta - 2 Years Monthly
A9: Narbada Gems and Jewellery Ltd | E9: SENSEX Bse Return
A11: Date | B11: Close Price | C11: Return | E11: Date | F11: Close Price | G11: Return | N11: SUMMARY OUTPUT
A12: 25-01-2026 | B12: 56.75 | E12: 25-01-2026 | F12: 82269.78 | I12: Beta Drafting
A13: 18-01-2026 | B13: 58.2 | C13: =B13/B12-1 -> 0.025550661 | E13: 18-01-2026 | F13: 81537.7 | G13: =F13/F12-1 -> -0.0088985287 | N13: Regression Statistics
A14: 46327 | B14: 63.88 | C14: =B14/B13-1 -> 0.097594502 | E14: 46327 | F14: 83570.35 | G14: =F14/F13-1 -> 0.024928959 | N14: Multiple R | O14: 0.025130431
A15: 46113 | B15: 64.18 | C15: =B15/B14-1 -> 0.0046963056 | E15: 46113 | F15: 83576.24 | G15: =F15/F14-1 -> 7.0479542e-05 | I15: Levered Raw Beta | J15: =O28 -> 0.1212999 | N15: R Square | O15: 0.00063153856
A16: 28-12-2025 | B16: 63.33 | C16: =B16/B15-1 -> -0.013244001 | E16: 28-12-2025 | F16: 85762.01 | G16: =F16/F15-1 -> 0.026153007 | I16: Raw Beta Weight | J16: 0.75 | N16: Adjusted R Square | O16: -0.0088862563
A17: 21-12-2025 | B17: 69.3 | C17: =B17/B16-1 -> 0.094268119 | E17: 21-12-2025 | F17: 85041.45 | G17: =F17/F16-1 -> -0.0084018553 | N17: Standard Error | O17: 0.080448883
A18: 14-12-2025 | B18: 63.76 | C18: =B18/B17-1 -> -0.07994228 | E18: 14-12-2025 | F18: 84929.36 | G18: =F18/F17-1 -> -0.0013180631 | I18: Market Beta | J18: 1 | N18: Observations | O18: 107
A19: 45850 | B19: 67.53 | C19: =B19/B18-1 -> 0.05912798 | E19: 45850 | F19: 85267.66 | G19: =F19/F18-1 -> 0.0039833104 | I19: Market Beta Weight | J19: 0.25
A20: 30-11-2025 | B20: 69.39 | C20: =B20/B19-1 -> 0.027543314 | E20: 30-11-2025 | F20: 85712.37 | G20: =F20/F19-1 -> 0.0052154592 | N20: ANOVA
A21: 23-11-2025 | B21: 68.61 | C21: =B21/B20-1 -> -0.011240813 | E21: 23-11-2025 | F21: 85706.67 | G21: =F21/F20-1 -> -6.6501486e-05 | I21: Adjusted Beta | J21: =(J15*J16)+(J18*J19) -> 0.34097493 | O21: df | P21: SS | Q21: MS | R21: F | S21: Significance F
A22: 16-11-2025 | B22: 68.99 | C22: =B22/B21-1 -> 0.0055385512 | E22: 16-11-2025 | F22: 85231.92 | G22: =F22/F21-1 -> -0.0055392422 | N22: Regression | O22: 1 | P22: 0.00042944106 | Q22: 0.00042944106 | R22: 0.066353454 | S22: 0.79722624
A23: 45911 | B23: 73.31 | C23: =B23/B22-1 -> 0.062617771 | E23: 45911 | F23: 84562.78 | G23: =F23/F22-1 -> -0.0078508146 | N23: Residual | O23: 105 | P23: 0.67956238 | Q23: 0.0064720227
A24: 45699 | B24: 69.06 | C24: =B24/B23-1 -> -0.057972991 | E24: 45699 | F24: 83216.28 | G24: =F24/F23-1 -> -0.015923081 | N24: Total | O24: 106 | P24: 0.67999182
A25: 26-10-2025 | B25: 72.98 | C25: =B25/B24-1 -> 0.056762236 | E25: 26-10-2025 | F25: 83938.71 | G25: =F25/F24-1 -> 0.0086813542
A26: 19-10-2025 | B26: 72.7 | C26: =B26/B25-1 -> -0.0038366676 | E26: 19-10-2025 | F26: 84211.88 | G26: =F26/F25-1 -> 0.0032543984 | O26: Coefficients | P26: Standard Error | Q26: t Stat | R26: P-value | S26: Lower 95% | T26: Upper 95% | U26: Lower 95.0% | V26: Upper 95.0%
A27: 46001 | B27: 69.95 | C27: =B27/B26-1 -> -0.037826685 | E27: 46001 | F27: 83952.19 | G27: =F27/F26-1 -> -0.0030837692 | N27: Intercept | O27: 0.0017738734 | P27: 0.0077947052 | Q27: 0.22757414 | R27: 0.82041986 | S27: -0.013681587 | T27: 0.017229334 | U27: -0.013681587 | V27: 0.017229334
A28: 45787 | B28: 72.77 | C28: =B28/B27-1 -> 0.04031451 | E28: 45787 | F28: 82500.82 | G28: =F28/F27-1 -> -0.017288054 | N28: X Variable 1 | O28: 0.1212999 | P28: 0.47089999 | Q28: 0.25759164 | R28: 0.79722624 | S28: -0.81240779 | T28: 1.0550076 | U28: -0.81240779 | V28: 1.0550076
A29: 28-09-2025 | B29: 69.62 | C29: =B29/B28-1 -> -0.043287069 | E29: 28-09-2025 | F29: 81207.17 | G29: =F29/F28-1 -> -0.01568045
A30: 21-09-2025 | B30: 69.27 | C30: =B30/B29-1 -> -0.005027291 | E30: 21-09-2025 | F30: 80426.46 | G30: =F30/F29-1 -> -0.0096138063
A31: 14-09-2025 | B31: 70.07 | C31: =B31/B30-1 -> 0.011549011 | E31: 14-09-2025 | F31: 82626.23 | G31: =F31/F30-1 -> 0.027351322
A32: 45847 | B32: 71.89 | C32: =B32/B31-1 -> 0.025974026 | E32: 45847 | F32: 81904.7 | G32: =F32/F31-1 -> -0.008732457
A33: 31-08-2025 | B33: 72.06 | C33: =B33/B32-1 -> 0.0023647239 | E33: 31-08-2025 | F33: 80710.76 | G33: =F33/F32-1 -> -0.014577185
A34: 24-08-2025 | B34: 70.12 | C34: =B34/B33-1 -> -0.026922009 | E34: 24-08-2025 | F34: 79809.65 | G34: =F34/F33-1 -> -0.011164682
A35: 17-08-2025 | B35: 73.59 | C35: =B35/B34-1 -> 0.049486594 | E35: 17-08-2025 | F35: 81306.85 | G35: =F35/F34-1 -> 0.018759636
A36: 45938 | B36: 55 | C36: =B36/B35-1 -> -0.25261584 | E36: 45938 | F36: 80597.66 | G36: =F36/F35-1 -> -0.0087223893
A37: 45724 | B37: 52.75 | C37: =B37/B36-1 -> -0.040909091 | E37: 45724 | F37: 79857.79 | G37: =F37/F36-1 -> -0.009179795
A38: 27-07-2025 | B38: 50.3 | C38: =B38/B37-1 -> -0.046445498 | E38: 27-07-2025 | F38: 80599.91 | G38: =F38/F37-1 -> 0.0092930195
A39: 20-07-2025 | B39: 50.07 | C39: =B39/B38-1 -> -0.0045725646 | E39: 20-07-2025 | F39: 81463.09 | G39: =F39/F38-1 -> 0.010709441
A40: 13-07-2025 | B40: 51.15 | C40: =B40/B39-1 -> 0.021569802 | E40: 13-07-2025 | F40: 81757.73 | G40: =F40/F39-1 -> 0.0036168527
A41: 45815 | B41: 53.5 | C41: =B41/B40-1 -> 0.045943304 | E41: 45815 | F41: 82500.47 | G41: =F41/F40-1 -> 0.0090846456
A42: 29-06-2025 | B42: 53.77 | C42: =B42/B41-1 -> 0.005046729 | E42: 29-06-2025 | F42: 83432.89 | G42: =F42/F41-1 -> 0.011301996
A43: 22-06-2025 | B43: 54.9 | C43: =B43/B42-1 -> 0.021015436 | E43: 22-06-2025 | F43: 84058.9 | G43: =F43/F42-1 -> 0.0075031561
A44: 15-06-2025 | B44: 54.95 | C44: =B44/B43-1 -> 0.00091074681 | E44: 15-06-2025 | F44: 82408.17 | G44: =F44/F43-1 -> -0.019637778
A45: 45875 | B45: 54.8 | C45: =B45/B44-1 -> -0.0027297543 | E45: 45875 | F45: 81118.6 | G45: =F45/F44-1 -> -0.01564857
A46: 45663 | B46: 52.68 | C46: =B46/B45-1 -> -0.038686131 | E46: 45663 | F46: 82188.99 | G46: =F46/F45-1 -> 0.013195371
A47: 25-05-2025 | B47: 56.02 | C47: =B47/B46-1 -> 0.06340167 | E47: 25-05-2025 | F47: 81451.01 | G47: =F47/F46-1 -> -0.0089790616
A48: 18-05-2025 | B48: 54.09 | C48: =B48/B47-1 -> -0.034451981 | E48: 18-05-2025 | F48: 81721.08 | G48: =F48/F47-1 -> 0.0033157354
...
